2020-04-12 19:03:08,909 - django.request - WARNING - Not Found: /favicon.ico
2020-04-12 19:03:14,368 - django.request - ERROR - Internal Server Error: /api/token
Traceback (most recent call last):
  File "/Users/jacksonbursch/Documents/csuMarkov/csuMarkov-server/markov/lib/python3.7/site-packages/django/core/handlers/exception.py", line 34, in inner
    response = get_response(request)
  File "/Users/jacksonbursch/Documents/csuMarkov/csuMarkov-server/markov/lib/python3.7/site-packages/django/core/handlers/base.py", line 115, in _get_response
    response = self.process_exception_by_middleware(e, request)
  File "/Users/jacksonbursch/Documents/csuMarkov/csuMarkov-server/markov/lib/python3.7/site-packages/django/core/handlers/base.py", line 113, in _get_response
    response = wrapped_callback(request, *callback_args, **callback_kwargs)
  File "/Users/jacksonbursch/Documents/csuMarkov/csuMarkov-server/markov/lib/python3.7/site-packages/django/views/decorators/csrf.py", line 54, in wrapped_view
    return view_func(*args, **kwargs)
  File "/Users/jacksonbursch/Documents/csuMarkov/csuMarkov-server/markov/lib/python3.7/site-packages/django/views/generic/base.py", line 71, in view
    return self.dispatch(request, *args, **kwargs)
  File "/Users/jacksonbursch/Documents/csuMarkov/csuMarkov-server/markov/lib/python3.7/site-packages/rest_framework/views.py", line 505, in dispatch
    response = self.handle_exception(exc)
  File "/Users/jacksonbursch/Documents/csuMarkov/csuMarkov-server/markov/lib/python3.7/site-packages/rest_framework/views.py", line 465, in handle_exception
    self.raise_uncaught_exception(exc)
  File "/Users/jacksonbursch/Documents/csuMarkov/csuMarkov-server/markov/lib/python3.7/site-packages/rest_framework/views.py", line 476, in raise_uncaught_exception
    raise exc
  File "/Users/jacksonbursch/Documents/csuMarkov/csuMarkov-server/markov/lib/python3.7/site-packages/rest_framework/views.py", line 502, in dispatch
    response = handler(request, *args, **kwargs)
  File "/Users/jacksonbursch/Documents/csuMarkov/csuMarkov-server/markov/lib/python3.7/site-packages/rest_framework_simplejwt/views.py", line 27, in post
    serializer.is_valid(raise_exception=True)
  File "/Users/jacksonbursch/Documents/csuMarkov/csuMarkov-server/markov/lib/python3.7/site-packages/rest_framework/serializers.py", line 234, in is_valid
    self._validated_data = self.run_validation(self.initial_data)
  File "/Users/jacksonbursch/Documents/csuMarkov/csuMarkov-server/markov/lib/python3.7/site-packages/rest_framework/serializers.py", line 436, in run_validation
    value = self.validate(value)
  File "/Users/jacksonbursch/Documents/csuMarkov/csuMarkov-server/markov/lib/python3.7/site-packages/rest_framework_simplejwt/serializers.py", line 75, in validate
    data['refresh'] = str(refresh)
  File "/Users/jacksonbursch/Documents/csuMarkov/csuMarkov-server/markov/lib/python3.7/site-packages/rest_framework_simplejwt/tokens.py", line 82, in __str__
    return token_backend.encode(self.payload)
  File "/Users/jacksonbursch/Documents/csuMarkov/csuMarkov-server/markov/lib/python3.7/site-packages/rest_framework_simplejwt/backends.py", line 42, in encode
    token = jwt.encode(jwt_payload, self.signing_key, algorithm=self.algorithm)
  File "/Users/jacksonbursch/Documents/csuMarkov/csuMarkov-server/markov/lib/python3.7/site-packages/jwt/api_jwt.py", line 65, in encode
    json_payload, key, algorithm, headers, json_encoder
  File "/Users/jacksonbursch/Documents/csuMarkov/csuMarkov-server/markov/lib/python3.7/site-packages/jwt/api_jws.py", line 113, in encode
    key = alg_obj.prepare_key(key)
  File "/Users/jacksonbursch/Documents/csuMarkov/csuMarkov-server/markov/lib/python3.7/site-packages/jwt/algorithms.py", line 140, in prepare_key
    key = force_bytes(key)
  File "/Users/jacksonbursch/Documents/csuMarkov/csuMarkov-server/markov/lib/python3.7/site-packages/jwt/utils.py", line 30, in force_bytes
    raise TypeError('Expected a string value')
TypeError: Expected a string value
2020-04-12 19:03:45,767 - django.utils.autoreload - INFO - /Users/jacksonbursch/Documents/csuMarkov/csuMarkov-server/server/server/settings.py changed, reloading.
2020-04-12 19:04:05,980 - django.request - WARNING - Not Found: /src/styles.less
2020-04-12 19:04:56,074 - django.request - WARNING - Method Not Allowed: /api/token
2020-04-12 19:05:09,313 - django.request - WARNING - Bad Request: /api/token
2020-04-12 19:06:08,958 - django.utils.autoreload - INFO - /Users/jacksonbursch/Documents/csuMarkov/csuMarkov-server/server/server/secret_constants.py changed, reloading.
2020-04-12 19:06:18,855 - django.utils.autoreload - INFO - /Users/jacksonbursch/Documents/csuMarkov/csuMarkov-server/server/server/settings.py changed, reloading.
2020-04-12 19:06:29,252 - django.request - ERROR - Internal Server Error: /api/token
Traceback (most recent call last):
  File "/Users/jacksonbursch/Documents/csuMarkov/csuMarkov-server/markov/lib/python3.7/site-packages/django/core/handlers/exception.py", line 34, in inner
    response = get_response(request)
  File "/Users/jacksonbursch/Documents/csuMarkov/csuMarkov-server/markov/lib/python3.7/site-packages/django/core/handlers/base.py", line 115, in _get_response
    response = self.process_exception_by_middleware(e, request)
  File "/Users/jacksonbursch/Documents/csuMarkov/csuMarkov-server/markov/lib/python3.7/site-packages/django/core/handlers/base.py", line 113, in _get_response
    response = wrapped_callback(request, *callback_args, **callback_kwargs)
  File "/Users/jacksonbursch/Documents/csuMarkov/csuMarkov-server/markov/lib/python3.7/site-packages/django/views/decorators/csrf.py", line 54, in wrapped_view
    return view_func(*args, **kwargs)
  File "/Users/jacksonbursch/Documents/csuMarkov/csuMarkov-server/markov/lib/python3.7/site-packages/django/views/generic/base.py", line 71, in view
    return self.dispatch(request, *args, **kwargs)
  File "/Users/jacksonbursch/Documents/csuMarkov/csuMarkov-server/markov/lib/python3.7/site-packages/rest_framework/views.py", line 505, in dispatch
    response = self.handle_exception(exc)
  File "/Users/jacksonbursch/Documents/csuMarkov/csuMarkov-server/markov/lib/python3.7/site-packages/rest_framework/views.py", line 465, in handle_exception
    self.raise_uncaught_exception(exc)
  File "/Users/jacksonbursch/Documents/csuMarkov/csuMarkov-server/markov/lib/python3.7/site-packages/rest_framework/views.py", line 476, in raise_uncaught_exception
    raise exc
  File "/Users/jacksonbursch/Documents/csuMarkov/csuMarkov-server/markov/lib/python3.7/site-packages/rest_framework/views.py", line 502, in dispatch
    response = handler(request, *args, **kwargs)
  File "/Users/jacksonbursch/Documents/csuMarkov/csuMarkov-server/markov/lib/python3.7/site-packages/rest_framework_simplejwt/views.py", line 27, in post
    serializer.is_valid(raise_exception=True)
  File "/Users/jacksonbursch/Documents/csuMarkov/csuMarkov-server/markov/lib/python3.7/site-packages/rest_framework/serializers.py", line 234, in is_valid
    self._validated_data = self.run_validation(self.initial_data)
  File "/Users/jacksonbursch/Documents/csuMarkov/csuMarkov-server/markov/lib/python3.7/site-packages/rest_framework/serializers.py", line 436, in run_validation
    value = self.validate(value)
  File "/Users/jacksonbursch/Documents/csuMarkov/csuMarkov-server/markov/lib/python3.7/site-packages/rest_framework_simplejwt/serializers.py", line 75, in validate
    data['refresh'] = str(refresh)
  File "/Users/jacksonbursch/Documents/csuMarkov/csuMarkov-server/markov/lib/python3.7/site-packages/rest_framework_simplejwt/tokens.py", line 82, in __str__
    return token_backend.encode(self.payload)
  File "/Users/jacksonbursch/Documents/csuMarkov/csuMarkov-server/markov/lib/python3.7/site-packages/rest_framework_simplejwt/backends.py", line 42, in encode
    token = jwt.encode(jwt_payload, self.signing_key, algorithm=self.algorithm)
  File "/Users/jacksonbursch/Documents/csuMarkov/csuMarkov-server/markov/lib/python3.7/site-packages/jwt/api_jwt.py", line 65, in encode
    json_payload, key, algorithm, headers, json_encoder
  File "/Users/jacksonbursch/Documents/csuMarkov/csuMarkov-server/markov/lib/python3.7/site-packages/jwt/api_jws.py", line 113, in encode
    key = alg_obj.prepare_key(key)
  File "/Users/jacksonbursch/Documents/csuMarkov/csuMarkov-server/markov/lib/python3.7/site-packages/jwt/algorithms.py", line 140, in prepare_key
    key = force_bytes(key)
  File "/Users/jacksonbursch/Documents/csuMarkov/csuMarkov-server/markov/lib/python3.7/site-packages/jwt/utils.py", line 30, in force_bytes
    raise TypeError('Expected a string value')
TypeError: Expected a string value
2020-04-12 19:16:33,796 - django.utils.autoreload - INFO - /Users/jacksonbursch/Documents/csuMarkov/csuMarkov-server/server/server/settings.py changed, reloading.
2020-04-12 19:16:41,096 - django.utils.autoreload - INFO - /Users/jacksonbursch/Documents/csuMarkov/csuMarkov-server/server/server/settings.py changed, reloading.
2020-04-12 19:17:17,984 - django.request - WARNING - Not Found: /api/token/
2020-04-12 19:17:22,975 - django.request - WARNING - Not Found: /api/token/
2020-04-12 19:17:30,783 - django.request - WARNING - Bad Request: /api/token
2020-04-12 19:26:12,360 - django.request - ERROR - Internal Server Error: /api/token
Traceback (most recent call last):
  File "/Users/jacksonbursch/Documents/csuMarkov/csuMarkov-server/markov/lib/python3.7/site-packages/django/core/handlers/exception.py", line 34, in inner
    response = get_response(request)
  File "/Users/jacksonbursch/Documents/csuMarkov/csuMarkov-server/markov/lib/python3.7/site-packages/django/core/handlers/base.py", line 115, in _get_response
    response = self.process_exception_by_middleware(e, request)
  File "/Users/jacksonbursch/Documents/csuMarkov/csuMarkov-server/markov/lib/python3.7/site-packages/django/core/handlers/base.py", line 113, in _get_response
    response = wrapped_callback(request, *callback_args, **callback_kwargs)
  File "/Users/jacksonbursch/Documents/csuMarkov/csuMarkov-server/markov/lib/python3.7/site-packages/django/views/decorators/csrf.py", line 54, in wrapped_view
    return view_func(*args, **kwargs)
  File "/Users/jacksonbursch/Documents/csuMarkov/csuMarkov-server/markov/lib/python3.7/site-packages/django/views/generic/base.py", line 71, in view
    return self.dispatch(request, *args, **kwargs)
  File "/Users/jacksonbursch/Documents/csuMarkov/csuMarkov-server/markov/lib/python3.7/site-packages/rest_framework/views.py", line 505, in dispatch
    response = self.handle_exception(exc)
  File "/Users/jacksonbursch/Documents/csuMarkov/csuMarkov-server/markov/lib/python3.7/site-packages/rest_framework/views.py", line 465, in handle_exception
    self.raise_uncaught_exception(exc)
  File "/Users/jacksonbursch/Documents/csuMarkov/csuMarkov-server/markov/lib/python3.7/site-packages/rest_framework/views.py", line 476, in raise_uncaught_exception
    raise exc
  File "/Users/jacksonbursch/Documents/csuMarkov/csuMarkov-server/markov/lib/python3.7/site-packages/rest_framework/views.py", line 502, in dispatch
    response = handler(request, *args, **kwargs)
  File "/Users/jacksonbursch/Documents/csuMarkov/csuMarkov-server/markov/lib/python3.7/site-packages/rest_framework_simplejwt/views.py", line 27, in post
    serializer.is_valid(raise_exception=True)
  File "/Users/jacksonbursch/Documents/csuMarkov/csuMarkov-server/markov/lib/python3.7/site-packages/rest_framework/serializers.py", line 234, in is_valid
    self._validated_data = self.run_validation(self.initial_data)
  File "/Users/jacksonbursch/Documents/csuMarkov/csuMarkov-server/markov/lib/python3.7/site-packages/rest_framework/serializers.py", line 436, in run_validation
    value = self.validate(value)
  File "/Users/jacksonbursch/Documents/csuMarkov/csuMarkov-server/markov/lib/python3.7/site-packages/rest_framework_simplejwt/serializers.py", line 75, in validate
    data['refresh'] = str(refresh)
  File "/Users/jacksonbursch/Documents/csuMarkov/csuMarkov-server/markov/lib/python3.7/site-packages/rest_framework_simplejwt/tokens.py", line 82, in __str__
    return token_backend.encode(self.payload)
  File "/Users/jacksonbursch/Documents/csuMarkov/csuMarkov-server/markov/lib/python3.7/site-packages/rest_framework_simplejwt/backends.py", line 42, in encode
    token = jwt.encode(jwt_payload, self.signing_key, algorithm=self.algorithm)
  File "/Users/jacksonbursch/Documents/csuMarkov/csuMarkov-server/markov/lib/python3.7/site-packages/jwt/api_jwt.py", line 65, in encode
    json_payload, key, algorithm, headers, json_encoder
  File "/Users/jacksonbursch/Documents/csuMarkov/csuMarkov-server/markov/lib/python3.7/site-packages/jwt/api_jws.py", line 113, in encode
    key = alg_obj.prepare_key(key)
  File "/Users/jacksonbursch/Documents/csuMarkov/csuMarkov-server/markov/lib/python3.7/site-packages/jwt/algorithms.py", line 140, in prepare_key
    key = force_bytes(key)
  File "/Users/jacksonbursch/Documents/csuMarkov/csuMarkov-server/markov/lib/python3.7/site-packages/jwt/utils.py", line 30, in force_bytes
    raise TypeError('Expected a string value')
TypeError: Expected a string value
2020-04-12 19:29:31,781 - django.utils.autoreload - INFO - /Users/jacksonbursch/Documents/csuMarkov/csuMarkov-server/server/server/secret_constants.py changed, reloading.
2020-04-12 19:29:38,171 - django.request - ERROR - Internal Server Error: /api/token
Traceback (most recent call last):
  File "/Users/jacksonbursch/Documents/csuMarkov/csuMarkov-server/markov/lib/python3.7/site-packages/django/core/handlers/exception.py", line 34, in inner
    response = get_response(request)
  File "/Users/jacksonbursch/Documents/csuMarkov/csuMarkov-server/markov/lib/python3.7/site-packages/django/core/handlers/base.py", line 115, in _get_response
    response = self.process_exception_by_middleware(e, request)
  File "/Users/jacksonbursch/Documents/csuMarkov/csuMarkov-server/markov/lib/python3.7/site-packages/django/core/handlers/base.py", line 113, in _get_response
    response = wrapped_callback(request, *callback_args, **callback_kwargs)
  File "/Users/jacksonbursch/Documents/csuMarkov/csuMarkov-server/markov/lib/python3.7/site-packages/django/views/decorators/csrf.py", line 54, in wrapped_view
    return view_func(*args, **kwargs)
  File "/Users/jacksonbursch/Documents/csuMarkov/csuMarkov-server/markov/lib/python3.7/site-packages/django/views/generic/base.py", line 71, in view
    return self.dispatch(request, *args, **kwargs)
  File "/Users/jacksonbursch/Documents/csuMarkov/csuMarkov-server/markov/lib/python3.7/site-packages/rest_framework/views.py", line 505, in dispatch
    response = self.handle_exception(exc)
  File "/Users/jacksonbursch/Documents/csuMarkov/csuMarkov-server/markov/lib/python3.7/site-packages/rest_framework/views.py", line 465, in handle_exception
    self.raise_uncaught_exception(exc)
  File "/Users/jacksonbursch/Documents/csuMarkov/csuMarkov-server/markov/lib/python3.7/site-packages/rest_framework/views.py", line 476, in raise_uncaught_exception
    raise exc
  File "/Users/jacksonbursch/Documents/csuMarkov/csuMarkov-server/markov/lib/python3.7/site-packages/rest_framework/views.py", line 502, in dispatch
    response = handler(request, *args, **kwargs)
  File "/Users/jacksonbursch/Documents/csuMarkov/csuMarkov-server/markov/lib/python3.7/site-packages/rest_framework_simplejwt/views.py", line 27, in post
    serializer.is_valid(raise_exception=True)
  File "/Users/jacksonbursch/Documents/csuMarkov/csuMarkov-server/markov/lib/python3.7/site-packages/rest_framework/serializers.py", line 234, in is_valid
    self._validated_data = self.run_validation(self.initial_data)
  File "/Users/jacksonbursch/Documents/csuMarkov/csuMarkov-server/markov/lib/python3.7/site-packages/rest_framework/serializers.py", line 436, in run_validation
    value = self.validate(value)
  File "/Users/jacksonbursch/Documents/csuMarkov/csuMarkov-server/markov/lib/python3.7/site-packages/rest_framework_simplejwt/serializers.py", line 75, in validate
    data['refresh'] = str(refresh)
  File "/Users/jacksonbursch/Documents/csuMarkov/csuMarkov-server/markov/lib/python3.7/site-packages/rest_framework_simplejwt/tokens.py", line 82, in __str__
    return token_backend.encode(self.payload)
  File "/Users/jacksonbursch/Documents/csuMarkov/csuMarkov-server/markov/lib/python3.7/site-packages/rest_framework_simplejwt/backends.py", line 42, in encode
    token = jwt.encode(jwt_payload, self.signing_key, algorithm=self.algorithm)
  File "/Users/jacksonbursch/Documents/csuMarkov/csuMarkov-server/markov/lib/python3.7/site-packages/jwt/api_jwt.py", line 65, in encode
    json_payload, key, algorithm, headers, json_encoder
  File "/Users/jacksonbursch/Documents/csuMarkov/csuMarkov-server/markov/lib/python3.7/site-packages/jwt/api_jws.py", line 113, in encode
    key = alg_obj.prepare_key(key)
  File "/Users/jacksonbursch/Documents/csuMarkov/csuMarkov-server/markov/lib/python3.7/site-packages/jwt/algorithms.py", line 140, in prepare_key
    key = force_bytes(key)
  File "/Users/jacksonbursch/Documents/csuMarkov/csuMarkov-server/markov/lib/python3.7/site-packages/jwt/utils.py", line 30, in force_bytes
    raise TypeError('Expected a string value')
TypeError: Expected a string value
2020-04-12 19:30:42,602 - django.utils.autoreload - INFO - /Users/jacksonbursch/Documents/csuMarkov/csuMarkov-server/server/server/secret_constants.py changed, reloading.
2020-04-12 19:30:47,836 - django.utils.autoreload - INFO - /Users/jacksonbursch/Documents/csuMarkov/csuMarkov-server/server/server/secret_constants.py changed, reloading.
2020-04-12 19:30:53,336 - django.request - ERROR - Internal Server Error: /api/token
Traceback (most recent call last):
  File "/Users/jacksonbursch/Documents/csuMarkov/csuMarkov-server/markov/lib/python3.7/site-packages/django/core/handlers/exception.py", line 34, in inner
    response = get_response(request)
  File "/Users/jacksonbursch/Documents/csuMarkov/csuMarkov-server/markov/lib/python3.7/site-packages/django/core/handlers/base.py", line 115, in _get_response
    response = self.process_exception_by_middleware(e, request)
  File "/Users/jacksonbursch/Documents/csuMarkov/csuMarkov-server/markov/lib/python3.7/site-packages/django/core/handlers/base.py", line 113, in _get_response
    response = wrapped_callback(request, *callback_args, **callback_kwargs)
  File "/Users/jacksonbursch/Documents/csuMarkov/csuMarkov-server/markov/lib/python3.7/site-packages/django/views/decorators/csrf.py", line 54, in wrapped_view
    return view_func(*args, **kwargs)
  File "/Users/jacksonbursch/Documents/csuMarkov/csuMarkov-server/markov/lib/python3.7/site-packages/django/views/generic/base.py", line 71, in view
    return self.dispatch(request, *args, **kwargs)
  File "/Users/jacksonbursch/Documents/csuMarkov/csuMarkov-server/markov/lib/python3.7/site-packages/rest_framework/views.py", line 505, in dispatch
    response = self.handle_exception(exc)
  File "/Users/jacksonbursch/Documents/csuMarkov/csuMarkov-server/markov/lib/python3.7/site-packages/rest_framework/views.py", line 465, in handle_exception
    self.raise_uncaught_exception(exc)
  File "/Users/jacksonbursch/Documents/csuMarkov/csuMarkov-server/markov/lib/python3.7/site-packages/rest_framework/views.py", line 476, in raise_uncaught_exception
    raise exc
  File "/Users/jacksonbursch/Documents/csuMarkov/csuMarkov-server/markov/lib/python3.7/site-packages/rest_framework/views.py", line 502, in dispatch
    response = handler(request, *args, **kwargs)
  File "/Users/jacksonbursch/Documents/csuMarkov/csuMarkov-server/markov/lib/python3.7/site-packages/rest_framework_simplejwt/views.py", line 27, in post
    serializer.is_valid(raise_exception=True)
  File "/Users/jacksonbursch/Documents/csuMarkov/csuMarkov-server/markov/lib/python3.7/site-packages/rest_framework/serializers.py", line 234, in is_valid
    self._validated_data = self.run_validation(self.initial_data)
  File "/Users/jacksonbursch/Documents/csuMarkov/csuMarkov-server/markov/lib/python3.7/site-packages/rest_framework/serializers.py", line 436, in run_validation
    value = self.validate(value)
  File "/Users/jacksonbursch/Documents/csuMarkov/csuMarkov-server/markov/lib/python3.7/site-packages/rest_framework_simplejwt/serializers.py", line 75, in validate
    data['refresh'] = str(refresh)
  File "/Users/jacksonbursch/Documents/csuMarkov/csuMarkov-server/markov/lib/python3.7/site-packages/rest_framework_simplejwt/tokens.py", line 82, in __str__
    return token_backend.encode(self.payload)
  File "/Users/jacksonbursch/Documents/csuMarkov/csuMarkov-server/markov/lib/python3.7/site-packages/rest_framework_simplejwt/backends.py", line 42, in encode
    token = jwt.encode(jwt_payload, self.signing_key, algorithm=self.algorithm)
  File "/Users/jacksonbursch/Documents/csuMarkov/csuMarkov-server/markov/lib/python3.7/site-packages/jwt/api_jwt.py", line 65, in encode
    json_payload, key, algorithm, headers, json_encoder
  File "/Users/jacksonbursch/Documents/csuMarkov/csuMarkov-server/markov/lib/python3.7/site-packages/jwt/api_jws.py", line 113, in encode
    key = alg_obj.prepare_key(key)
  File "/Users/jacksonbursch/Documents/csuMarkov/csuMarkov-server/markov/lib/python3.7/site-packages/jwt/algorithms.py", line 140, in prepare_key
    key = force_bytes(key)
  File "/Users/jacksonbursch/Documents/csuMarkov/csuMarkov-server/markov/lib/python3.7/site-packages/jwt/utils.py", line 30, in force_bytes
    raise TypeError('Expected a string value')
TypeError: Expected a string value
2020-04-12 19:31:40,851 - django.utils.autoreload - INFO - /Users/jacksonbursch/Documents/csuMarkov/csuMarkov-server/server/server/settings.py changed, reloading.
2020-04-12 19:31:53,780 - django.request - ERROR - Internal Server Error: /api/token
Traceback (most recent call last):
  File "/Users/jacksonbursch/Documents/csuMarkov/csuMarkov-server/markov/lib/python3.7/site-packages/django/core/handlers/exception.py", line 34, in inner
    response = get_response(request)
  File "/Users/jacksonbursch/Documents/csuMarkov/csuMarkov-server/markov/lib/python3.7/site-packages/django/core/handlers/base.py", line 115, in _get_response
    response = self.process_exception_by_middleware(e, request)
  File "/Users/jacksonbursch/Documents/csuMarkov/csuMarkov-server/markov/lib/python3.7/site-packages/django/core/handlers/base.py", line 113, in _get_response
    response = wrapped_callback(request, *callback_args, **callback_kwargs)
  File "/Users/jacksonbursch/Documents/csuMarkov/csuMarkov-server/markov/lib/python3.7/site-packages/django/views/decorators/csrf.py", line 54, in wrapped_view
    return view_func(*args, **kwargs)
  File "/Users/jacksonbursch/Documents/csuMarkov/csuMarkov-server/markov/lib/python3.7/site-packages/django/views/generic/base.py", line 71, in view
    return self.dispatch(request, *args, **kwargs)
  File "/Users/jacksonbursch/Documents/csuMarkov/csuMarkov-server/markov/lib/python3.7/site-packages/rest_framework/views.py", line 505, in dispatch
    response = self.handle_exception(exc)
  File "/Users/jacksonbursch/Documents/csuMarkov/csuMarkov-server/markov/lib/python3.7/site-packages/rest_framework/views.py", line 465, in handle_exception
    self.raise_uncaught_exception(exc)
  File "/Users/jacksonbursch/Documents/csuMarkov/csuMarkov-server/markov/lib/python3.7/site-packages/rest_framework/views.py", line 476, in raise_uncaught_exception
    raise exc
  File "/Users/jacksonbursch/Documents/csuMarkov/csuMarkov-server/markov/lib/python3.7/site-packages/rest_framework/views.py", line 502, in dispatch
    response = handler(request, *args, **kwargs)
  File "/Users/jacksonbursch/Documents/csuMarkov/csuMarkov-server/markov/lib/python3.7/site-packages/rest_framework_simplejwt/views.py", line 27, in post
    serializer.is_valid(raise_exception=True)
  File "/Users/jacksonbursch/Documents/csuMarkov/csuMarkov-server/markov/lib/python3.7/site-packages/rest_framework/serializers.py", line 234, in is_valid
    self._validated_data = self.run_validation(self.initial_data)
  File "/Users/jacksonbursch/Documents/csuMarkov/csuMarkov-server/markov/lib/python3.7/site-packages/rest_framework/serializers.py", line 436, in run_validation
    value = self.validate(value)
  File "/Users/jacksonbursch/Documents/csuMarkov/csuMarkov-server/markov/lib/python3.7/site-packages/rest_framework_simplejwt/serializers.py", line 75, in validate
    data['refresh'] = str(refresh)
  File "/Users/jacksonbursch/Documents/csuMarkov/csuMarkov-server/markov/lib/python3.7/site-packages/rest_framework_simplejwt/tokens.py", line 82, in __str__
    return token_backend.encode(self.payload)
  File "/Users/jacksonbursch/Documents/csuMarkov/csuMarkov-server/markov/lib/python3.7/site-packages/rest_framework_simplejwt/backends.py", line 42, in encode
    token = jwt.encode(jwt_payload, self.signing_key, algorithm=self.algorithm)
  File "/Users/jacksonbursch/Documents/csuMarkov/csuMarkov-server/markov/lib/python3.7/site-packages/jwt/api_jwt.py", line 65, in encode
    json_payload, key, algorithm, headers, json_encoder
  File "/Users/jacksonbursch/Documents/csuMarkov/csuMarkov-server/markov/lib/python3.7/site-packages/jwt/api_jws.py", line 113, in encode
    key = alg_obj.prepare_key(key)
  File "/Users/jacksonbursch/Documents/csuMarkov/csuMarkov-server/markov/lib/python3.7/site-packages/jwt/algorithms.py", line 140, in prepare_key
    key = force_bytes(key)
  File "/Users/jacksonbursch/Documents/csuMarkov/csuMarkov-server/markov/lib/python3.7/site-packages/jwt/utils.py", line 30, in force_bytes
    raise TypeError('Expected a string value')
TypeError: Expected a string value
2020-04-12 19:32:17,799 - django.utils.autoreload - INFO - /Users/jacksonbursch/Documents/csuMarkov/csuMarkov-server/server/server/settings.py changed, reloading.
2020-04-12 19:32:23,339 - django.request - ERROR - Internal Server Error: /api/token
Traceback (most recent call last):
  File "/Users/jacksonbursch/Documents/csuMarkov/csuMarkov-server/markov/lib/python3.7/site-packages/django/core/handlers/exception.py", line 34, in inner
    response = get_response(request)
  File "/Users/jacksonbursch/Documents/csuMarkov/csuMarkov-server/markov/lib/python3.7/site-packages/django/core/handlers/base.py", line 115, in _get_response
    response = self.process_exception_by_middleware(e, request)
  File "/Users/jacksonbursch/Documents/csuMarkov/csuMarkov-server/markov/lib/python3.7/site-packages/django/core/handlers/base.py", line 113, in _get_response
    response = wrapped_callback(request, *callback_args, **callback_kwargs)
  File "/Users/jacksonbursch/Documents/csuMarkov/csuMarkov-server/markov/lib/python3.7/site-packages/django/views/decorators/csrf.py", line 54, in wrapped_view
    return view_func(*args, **kwargs)
  File "/Users/jacksonbursch/Documents/csuMarkov/csuMarkov-server/markov/lib/python3.7/site-packages/django/views/generic/base.py", line 71, in view
    return self.dispatch(request, *args, **kwargs)
  File "/Users/jacksonbursch/Documents/csuMarkov/csuMarkov-server/markov/lib/python3.7/site-packages/rest_framework/views.py", line 505, in dispatch
    response = self.handle_exception(exc)
  File "/Users/jacksonbursch/Documents/csuMarkov/csuMarkov-server/markov/lib/python3.7/site-packages/rest_framework/views.py", line 465, in handle_exception
    self.raise_uncaught_exception(exc)
  File "/Users/jacksonbursch/Documents/csuMarkov/csuMarkov-server/markov/lib/python3.7/site-packages/rest_framework/views.py", line 476, in raise_uncaught_exception
    raise exc
  File "/Users/jacksonbursch/Documents/csuMarkov/csuMarkov-server/markov/lib/python3.7/site-packages/rest_framework/views.py", line 502, in dispatch
    response = handler(request, *args, **kwargs)
  File "/Users/jacksonbursch/Documents/csuMarkov/csuMarkov-server/markov/lib/python3.7/site-packages/rest_framework_simplejwt/views.py", line 27, in post
    serializer.is_valid(raise_exception=True)
  File "/Users/jacksonbursch/Documents/csuMarkov/csuMarkov-server/markov/lib/python3.7/site-packages/rest_framework/serializers.py", line 234, in is_valid
    self._validated_data = self.run_validation(self.initial_data)
  File "/Users/jacksonbursch/Documents/csuMarkov/csuMarkov-server/markov/lib/python3.7/site-packages/rest_framework/serializers.py", line 436, in run_validation
    value = self.validate(value)
  File "/Users/jacksonbursch/Documents/csuMarkov/csuMarkov-server/markov/lib/python3.7/site-packages/rest_framework_simplejwt/serializers.py", line 75, in validate
    data['refresh'] = str(refresh)
  File "/Users/jacksonbursch/Documents/csuMarkov/csuMarkov-server/markov/lib/python3.7/site-packages/rest_framework_simplejwt/tokens.py", line 82, in __str__
    return token_backend.encode(self.payload)
  File "/Users/jacksonbursch/Documents/csuMarkov/csuMarkov-server/markov/lib/python3.7/site-packages/rest_framework_simplejwt/backends.py", line 42, in encode
    token = jwt.encode(jwt_payload, self.signing_key, algorithm=self.algorithm)
  File "/Users/jacksonbursch/Documents/csuMarkov/csuMarkov-server/markov/lib/python3.7/site-packages/jwt/api_jwt.py", line 65, in encode
    json_payload, key, algorithm, headers, json_encoder
  File "/Users/jacksonbursch/Documents/csuMarkov/csuMarkov-server/markov/lib/python3.7/site-packages/jwt/api_jws.py", line 113, in encode
    key = alg_obj.prepare_key(key)
  File "/Users/jacksonbursch/Documents/csuMarkov/csuMarkov-server/markov/lib/python3.7/site-packages/jwt/algorithms.py", line 140, in prepare_key
    key = force_bytes(key)
  File "/Users/jacksonbursch/Documents/csuMarkov/csuMarkov-server/markov/lib/python3.7/site-packages/jwt/utils.py", line 30, in force_bytes
    raise TypeError('Expected a string value')
TypeError: Expected a string value
2020-04-13 02:04:32,483 - django.utils.autoreload - INFO - /Users/jacksonbursch/Documents/csuMarkov/csuMarkov-server/server/server/settings.py changed, reloading.
2020-04-13 02:11:02,702 - django.utils.autoreload - INFO - /Users/jacksonbursch/Documents/csuMarkov/csuMarkov-server/server/server/settings.py changed, reloading.
2020-04-13 02:12:51,789 - django.utils.autoreload - INFO - /Users/jacksonbursch/Documents/csuMarkov/csuMarkov-server/server/server/settings.py changed, reloading.
2020-04-13 02:14:51,794 - django.utils.autoreload - INFO - /Users/jacksonbursch/Documents/csuMarkov/csuMarkov-server/server/server/settings.py changed, reloading.
2020-04-13 02:15:03,946 - django.utils.autoreload - INFO - /Users/jacksonbursch/Documents/csuMarkov/csuMarkov-server/server/server/settings.py changed, reloading.
2020-04-13 02:17:27,021 - django.utils.autoreload - INFO - /Users/jacksonbursch/Documents/csuMarkov/csuMarkov-server/server/server/settings.py changed, reloading.
2020-04-13 02:21:21,204 - django.utils.autoreload - INFO - /Users/jacksonbursch/Documents/csuMarkov/csuMarkov-server/server/server/settings.py changed, reloading.
2020-04-13 02:22:30,830 - django.utils.autoreload - INFO - /Users/jacksonbursch/Documents/csuMarkov/csuMarkov-server/server/insert2DB/views.py changed, reloading.
2020-04-13 02:22:45,779 - django.utils.autoreload - INFO - /Users/jacksonbursch/Documents/csuMarkov/csuMarkov-server/server/insert2DB/models.py changed, reloading.
2020-04-13 02:23:04,451 - django.utils.autoreload - INFO - /Users/jacksonbursch/Documents/csuMarkov/csuMarkov-server/server/insert2DB/cohortModel.py changed, reloading.
2020-04-21 00:22:26,800 - django.request - WARNING - Not Found: /createToken
2020-04-21 00:53:33,225 - django.utils.autoreload - INFO - /Users/jacksonbursch/Documents/csuSeer/csuSeer-server/server/insert2DB/views.py changed, reloading.
2020-04-21 00:55:59,194 - django.utils.autoreload - INFO - /Users/jacksonbursch/Documents/csuSeer/csuSeer-server/server/insert2DB/views.py changed, reloading.
2020-04-21 00:56:10,087 - django.request - ERROR - Internal Server Error: /permission/
Traceback (most recent call last):
  File "/usr/local/lib/python3.7/site-packages/django/core/handlers/exception.py", line 34, in inner
    response = get_response(request)
  File "/usr/local/lib/python3.7/site-packages/django/core/handlers/base.py", line 115, in _get_response
    response = self.process_exception_by_middleware(e, request)
  File "/usr/local/lib/python3.7/site-packages/django/core/handlers/base.py", line 113, in _get_response
    response = wrapped_callback(request, *callback_args, **callback_kwargs)
  File "/usr/local/lib/python3.7/site-packages/django/views/decorators/csrf.py", line 54, in wrapped_view
    return view_func(*args, **kwargs)
  File "/usr/local/lib/python3.7/site-packages/django/views/decorators/csrf.py", line 54, in wrapped_view
    return view_func(*args, **kwargs)
  File "/usr/local/lib/python3.7/site-packages/django/views/generic/base.py", line 71, in view
    return self.dispatch(request, *args, **kwargs)
  File "/usr/local/lib/python3.7/site-packages/rest_framework/views.py", line 505, in dispatch
    response = self.handle_exception(exc)
  File "/usr/local/lib/python3.7/site-packages/rest_framework/views.py", line 465, in handle_exception
    self.raise_uncaught_exception(exc)
  File "/usr/local/lib/python3.7/site-packages/rest_framework/views.py", line 476, in raise_uncaught_exception
    raise exc
  File "/usr/local/lib/python3.7/site-packages/rest_framework/views.py", line 502, in dispatch
    response = handler(request, *args, **kwargs)
  File "/usr/local/lib/python3.7/site-packages/rest_framework/decorators.py", line 50, in handler
    return func(*args, **kwargs)
  File "/Users/jacksonbursch/Documents/csuSeer/csuSeer-server/server/insert2DB/views.py", line 93, in givePerm
    user.user_permissions.add(all_permissions)
  File "/usr/local/lib/python3.7/site-packages/django/db/models/fields/related_descriptors.py", line 938, in add
    through_defaults=through_defaults,
  File "/usr/local/lib/python3.7/site-packages/django/db/models/fields/related_descriptors.py", line 1065, in _add_items
    '%s__in' % target_field_name: new_ids,
  File "/usr/local/lib/python3.7/site-packages/django/db/models/query.py", line 892, in filter
    return self._filter_or_exclude(False, *args, **kwargs)
  File "/usr/local/lib/python3.7/site-packages/django/db/models/query.py", line 910, in _filter_or_exclude
    clone.query.add_q(Q(*args, **kwargs))
  File "/usr/local/lib/python3.7/site-packages/django/db/models/sql/query.py", line 1290, in add_q
    clause, _ = self._add_q(q_object, self.used_aliases)
  File "/usr/local/lib/python3.7/site-packages/django/db/models/sql/query.py", line 1318, in _add_q
    split_subq=split_subq, simple_col=simple_col,
  File "/usr/local/lib/python3.7/site-packages/django/db/models/sql/query.py", line 1251, in build_filter
    condition = self.build_lookup(lookups, col, value)
  File "/usr/local/lib/python3.7/site-packages/django/db/models/sql/query.py", line 1116, in build_lookup
    lookup = lookup_class(lhs, rhs)
  File "/usr/local/lib/python3.7/site-packages/django/db/models/lookups.py", line 20, in __init__
    self.rhs = self.get_prep_lookup()
  File "/usr/local/lib/python3.7/site-packages/django/db/models/fields/related_lookups.py", line 59, in get_prep_lookup
    self.rhs = [target_field.get_prep_value(v) for v in self.rhs]
  File "/usr/local/lib/python3.7/site-packages/django/db/models/fields/related_lookups.py", line 59, in <listcomp>
    self.rhs = [target_field.get_prep_value(v) for v in self.rhs]
  File "/usr/local/lib/python3.7/site-packages/django/db/models/fields/__init__.py", line 972, in get_prep_value
    return int(value)
TypeError: int() argument must be a string, a bytes-like object or a number, not 'QuerySet'
2020-04-21 00:59:23,568 - django.utils.autoreload - INFO - /Users/jacksonbursch/Documents/csuSeer/csuSeer-server/server/insert2DB/models.py changed, reloading.
2020-04-21 01:03:54,292 - django.request - ERROR - Internal Server Error: /createUser/
Traceback (most recent call last):
  File "/usr/local/lib/python3.7/site-packages/django/core/handlers/exception.py", line 34, in inner
    response = get_response(request)
  File "/usr/local/lib/python3.7/site-packages/django/core/handlers/base.py", line 115, in _get_response
    response = self.process_exception_by_middleware(e, request)
  File "/usr/local/lib/python3.7/site-packages/django/core/handlers/base.py", line 113, in _get_response
    response = wrapped_callback(request, *callback_args, **callback_kwargs)
  File "/usr/local/lib/python3.7/site-packages/django/views/decorators/csrf.py", line 54, in wrapped_view
    return view_func(*args, **kwargs)
  File "/usr/local/lib/python3.7/site-packages/django/views/decorators/csrf.py", line 54, in wrapped_view
    return view_func(*args, **kwargs)
  File "/usr/local/lib/python3.7/site-packages/django/views/generic/base.py", line 71, in view
    return self.dispatch(request, *args, **kwargs)
  File "/usr/local/lib/python3.7/site-packages/rest_framework/views.py", line 505, in dispatch
    response = self.handle_exception(exc)
  File "/usr/local/lib/python3.7/site-packages/rest_framework/views.py", line 465, in handle_exception
    self.raise_uncaught_exception(exc)
  File "/usr/local/lib/python3.7/site-packages/rest_framework/views.py", line 476, in raise_uncaught_exception
    raise exc
  File "/usr/local/lib/python3.7/site-packages/rest_framework/views.py", line 502, in dispatch
    response = handler(request, *args, **kwargs)
  File "/usr/local/lib/python3.7/site-packages/rest_framework/decorators.py", line 50, in handler
    return func(*args, **kwargs)
  File "/Users/jacksonbursch/Documents/csuSeer/csuSeer-server/server/insert2DB/views.py", line 67, in createUser
    user = SystemConsumer.objects.create_user(username = request.data.get('username'),
AttributeError: 'Manager' object has no attribute 'create_user'
2020-04-21 01:04:11,099 - django.utils.autoreload - INFO - /Users/jacksonbursch/Documents/csuSeer/csuSeer-server/server/insert2DB/views.py changed, reloading.
2020-04-21 01:04:17,119 - django.request - ERROR - Internal Server Error: /createUser/
Traceback (most recent call last):
  File "/usr/local/lib/python3.7/site-packages/django/core/handlers/exception.py", line 34, in inner
    response = get_response(request)
  File "/usr/local/lib/python3.7/site-packages/django/core/handlers/base.py", line 115, in _get_response
    response = self.process_exception_by_middleware(e, request)
  File "/usr/local/lib/python3.7/site-packages/django/core/handlers/base.py", line 113, in _get_response
    response = wrapped_callback(request, *callback_args, **callback_kwargs)
  File "/usr/local/lib/python3.7/site-packages/django/views/decorators/csrf.py", line 54, in wrapped_view
    return view_func(*args, **kwargs)
  File "/usr/local/lib/python3.7/site-packages/django/views/decorators/csrf.py", line 54, in wrapped_view
    return view_func(*args, **kwargs)
  File "/usr/local/lib/python3.7/site-packages/django/views/generic/base.py", line 71, in view
    return self.dispatch(request, *args, **kwargs)
  File "/usr/local/lib/python3.7/site-packages/rest_framework/views.py", line 505, in dispatch
    response = self.handle_exception(exc)
  File "/usr/local/lib/python3.7/site-packages/rest_framework/views.py", line 465, in handle_exception
    self.raise_uncaught_exception(exc)
  File "/usr/local/lib/python3.7/site-packages/rest_framework/views.py", line 476, in raise_uncaught_exception
    raise exc
  File "/usr/local/lib/python3.7/site-packages/rest_framework/views.py", line 502, in dispatch
    response = handler(request, *args, **kwargs)
  File "/usr/local/lib/python3.7/site-packages/rest_framework/decorators.py", line 50, in handler
    return func(*args, **kwargs)
  File "/Users/jacksonbursch/Documents/csuSeer/csuSeer-server/server/insert2DB/views.py", line 69, in createUser
    password = request.data.get('password'))
  File "/usr/local/lib/python3.7/site-packages/django/db/models/manager.py", line 82, in manager_method
    return getattr(self.get_queryset(), name)(*args, **kwargs)
  File "/usr/local/lib/python3.7/site-packages/django/db/models/query.py", line 422, in create
    obj.save(force_insert=True, using=self.db)
  File "/usr/local/lib/python3.7/site-packages/django/db/models/base.py", line 741, in save
    force_update=force_update, update_fields=update_fields)
  File "/usr/local/lib/python3.7/site-packages/django/db/models/base.py", line 776, in save_base
    parent_inserted = self._save_parents(cls, using, update_fields)
  File "/usr/local/lib/python3.7/site-packages/django/db/models/base.py", line 804, in _save_parents
    parent_inserted = self._save_parents(cls=parent, using=using, update_fields=update_fields)
  File "/usr/local/lib/python3.7/site-packages/django/db/models/base.py", line 807, in _save_parents
    force_insert=parent_inserted,
  File "/usr/local/lib/python3.7/site-packages/django/db/models/base.py", line 870, in _save_table
    result = self._do_insert(cls._base_manager, using, fields, update_pk, raw)
  File "/usr/local/lib/python3.7/site-packages/django/db/models/base.py", line 908, in _do_insert
    using=using, raw=raw)
  File "/usr/local/lib/python3.7/site-packages/django/db/models/manager.py", line 82, in manager_method
    return getattr(self.get_queryset(), name)(*args, **kwargs)
  File "/usr/local/lib/python3.7/site-packages/django/db/models/query.py", line 1186, in _insert
    return query.get_compiler(using=using).execute_sql(return_id)
  File "/usr/local/lib/python3.7/site-packages/django/db/models/sql/compiler.py", line 1367, in execute_sql
    for sql, params in self.as_sql():
  File "/usr/local/lib/python3.7/site-packages/django/db/models/sql/compiler.py", line 1311, in as_sql
    for obj in self.query.objs
  File "/usr/local/lib/python3.7/site-packages/django/db/models/sql/compiler.py", line 1311, in <listcomp>
    for obj in self.query.objs
  File "/usr/local/lib/python3.7/site-packages/django/db/models/sql/compiler.py", line 1310, in <listcomp>
    [self.prepare_value(field, self.pre_save_val(field, obj)) for field in fields]
  File "/usr/local/lib/python3.7/site-packages/django/db/models/sql/compiler.py", line 1251, in prepare_value
    value = field.get_db_prep_save(value, connection=self.connection)
  File "/usr/local/lib/python3.7/site-packages/django/db/models/fields/related.py", line 937, in get_db_prep_save
    return self.target_field.get_db_prep_save(value, connection=connection)
  File "/usr/local/lib/python3.7/site-packages/django/db/models/fields/__init__.py", line 793, in get_db_prep_save
    return self.get_db_prep_value(value, connection=connection, prepared=False)
  File "/usr/local/lib/python3.7/site-packages/django/db/models/fields/__init__.py", line 963, in get_db_prep_value
    value = self.get_prep_value(value)
  File "/usr/local/lib/python3.7/site-packages/django/db/models/fields/__init__.py", line 972, in get_prep_value
    return int(value)
TypeError: int() argument must be a string, a bytes-like object or a number, not 'ObjectId'
2020-04-21 01:04:46,128 - django.utils.autoreload - INFO - /Users/jacksonbursch/Documents/csuSeer/csuSeer-server/server/insert2DB/views.py changed, reloading.
2020-04-21 01:04:49,601 - django.request - ERROR - Internal Server Error: /createUser/
Traceback (most recent call last):
  File "/usr/local/lib/python3.7/site-packages/djongo/sql2mongo/query.py", line 824, in parse
    return handler(self, statement)
  File "/usr/local/lib/python3.7/site-packages/djongo/sql2mongo/query.py", line 960, in _insert
    self._query.execute()
  File "/usr/local/lib/python3.7/site-packages/djongo/sql2mongo/query.py", line 430, in execute
    res = self.db_ref[self.left_table].insert_many(docs, ordered=False)
  File "/usr/local/lib/python3.7/site-packages/pymongo/collection.py", line 758, in insert_many
    blk.execute(write_concern, session=session)
  File "/usr/local/lib/python3.7/site-packages/pymongo/bulk.py", line 511, in execute
    return self.execute_command(generator, write_concern, session)
  File "/usr/local/lib/python3.7/site-packages/pymongo/bulk.py", line 349, in execute_command
    _raise_bulk_write_error(full_result)
  File "/usr/local/lib/python3.7/site-packages/pymongo/bulk.py", line 140, in _raise_bulk_write_error
    raise BulkWriteError(full_result)
pymongo.errors.BulkWriteError: batch op errors occurred

The above exception was the direct cause of the following exception:

Traceback (most recent call last):
  File "/usr/local/lib/python3.7/site-packages/django/core/handlers/exception.py", line 34, in inner
    response = get_response(request)
  File "/usr/local/lib/python3.7/site-packages/django/core/handlers/base.py", line 115, in _get_response
    response = self.process_exception_by_middleware(e, request)
  File "/usr/local/lib/python3.7/site-packages/django/core/handlers/base.py", line 113, in _get_response
    response = wrapped_callback(request, *callback_args, **callback_kwargs)
  File "/usr/local/lib/python3.7/site-packages/django/views/decorators/csrf.py", line 54, in wrapped_view
    return view_func(*args, **kwargs)
  File "/usr/local/lib/python3.7/site-packages/django/views/decorators/csrf.py", line 54, in wrapped_view
    return view_func(*args, **kwargs)
  File "/usr/local/lib/python3.7/site-packages/django/views/generic/base.py", line 71, in view
    return self.dispatch(request, *args, **kwargs)
  File "/usr/local/lib/python3.7/site-packages/rest_framework/views.py", line 505, in dispatch
    response = self.handle_exception(exc)
  File "/usr/local/lib/python3.7/site-packages/rest_framework/views.py", line 465, in handle_exception
    self.raise_uncaught_exception(exc)
  File "/usr/local/lib/python3.7/site-packages/rest_framework/views.py", line 476, in raise_uncaught_exception
    raise exc
  File "/usr/local/lib/python3.7/site-packages/rest_framework/views.py", line 502, in dispatch
    response = handler(request, *args, **kwargs)
  File "/usr/local/lib/python3.7/site-packages/rest_framework/decorators.py", line 50, in handler
    return func(*args, **kwargs)
  File "/Users/jacksonbursch/Documents/csuSeer/csuSeer-server/server/insert2DB/views.py", line 69, in createUser
    password = request.POST.get('password'))
  File "/usr/local/lib/python3.7/site-packages/django/db/models/manager.py", line 82, in manager_method
    return getattr(self.get_queryset(), name)(*args, **kwargs)
  File "/usr/local/lib/python3.7/site-packages/django/db/models/query.py", line 422, in create
    obj.save(force_insert=True, using=self.db)
  File "/usr/local/lib/python3.7/site-packages/django/db/models/base.py", line 741, in save
    force_update=force_update, update_fields=update_fields)
  File "/usr/local/lib/python3.7/site-packages/django/db/models/base.py", line 776, in save_base
    parent_inserted = self._save_parents(cls, using, update_fields)
  File "/usr/local/lib/python3.7/site-packages/django/db/models/base.py", line 804, in _save_parents
    parent_inserted = self._save_parents(cls=parent, using=using, update_fields=update_fields)
  File "/usr/local/lib/python3.7/site-packages/django/db/models/base.py", line 804, in _save_parents
    parent_inserted = self._save_parents(cls=parent, using=using, update_fields=update_fields)
  File "/usr/local/lib/python3.7/site-packages/django/db/models/base.py", line 807, in _save_parents
    force_insert=parent_inserted,
  File "/usr/local/lib/python3.7/site-packages/django/db/models/base.py", line 870, in _save_table
    result = self._do_insert(cls._base_manager, using, fields, update_pk, raw)
  File "/usr/local/lib/python3.7/site-packages/django/db/models/base.py", line 908, in _do_insert
    using=using, raw=raw)
  File "/usr/local/lib/python3.7/site-packages/django/db/models/manager.py", line 82, in manager_method
    return getattr(self.get_queryset(), name)(*args, **kwargs)
  File "/usr/local/lib/python3.7/site-packages/django/db/models/query.py", line 1186, in _insert
    return query.get_compiler(using=using).execute_sql(return_id)
  File "/usr/local/lib/python3.7/site-packages/django/db/models/sql/compiler.py", line 1368, in execute_sql
    cursor.execute(sql, params)
  File "/usr/local/lib/python3.7/site-packages/django/db/backends/utils.py", line 99, in execute
    return super().execute(sql, params)
  File "/usr/local/lib/python3.7/site-packages/django/db/backends/utils.py", line 67, in execute
    return self._execute_with_wrappers(sql, params, many=False, executor=self._execute)
  File "/usr/local/lib/python3.7/site-packages/django/db/backends/utils.py", line 76, in _execute_with_wrappers
    return executor(sql, params, many, context)
  File "/usr/local/lib/python3.7/site-packages/django/db/backends/utils.py", line 84, in _execute
    return self.cursor.execute(sql, params)
  File "/usr/local/lib/python3.7/site-packages/djongo/cursor.py", line 53, in execute
    params)
  File "/usr/local/lib/python3.7/site-packages/djongo/sql2mongo/query.py", line 753, in __init__
    self.parse()
  File "/usr/local/lib/python3.7/site-packages/djongo/sql2mongo/query.py", line 837, in parse
    raise exe from e
djongo.sql2mongo.SQLDecodeError: FAILED SQL: INSERT INTO "insert2DB_deptconsumer" ("username", "password", "email") VALUES (%(0)s, %(1)s, %(2)s)
Params: ['jaxon13', 'hello1', 'hello@gmail.com']
Pymongo error: {'writeErrors': [{'index': 0, 'code': 11000, 'keyPattern': {'user_ptr_id': 1}, 'keyValue': {'user_ptr_id': None}, 'errmsg': 'E11000 duplicate key error collection: csuSeerDB.insert2DB_deptconsumer index: __primary_key__ dup key: { user_ptr_id: null }', 'op': {'username': 'jaxon13', 'password': 'hello1', 'email': 'hello@gmail.com', '_id': ObjectId('5e9e46b1d3a55808492b0905')}}], 'writeConcernErrors': [], 'nInserted': 0, 'nUpserted': 0, 'nMatched': 0, 'nModified': 0, 'nRemoved': 0, 'upserted': []}
Version: 1.3.1
2020-04-21 01:06:05,613 - django.utils.autoreload - INFO - /Users/jacksonbursch/Documents/csuSeer/csuSeer-server/server/insert2DB/views.py changed, reloading.
2020-04-21 01:08:28,897 - django.utils.autoreload - INFO - /Users/jacksonbursch/Documents/csuSeer/csuSeer-server/server/insert2DB/models.py changed, reloading.
2020-04-21 01:10:26,596 - django.utils.autoreload - INFO - /Users/jacksonbursch/Documents/csuSeer/csuSeer-server/server/insert2DB/views.py changed, reloading.
2020-04-21 01:10:35,920 - django.request - ERROR - Internal Server Error: /createUser/
Traceback (most recent call last):
  File "/usr/local/lib/python3.7/site-packages/django/core/handlers/exception.py", line 34, in inner
    response = get_response(request)
  File "/usr/local/lib/python3.7/site-packages/django/core/handlers/base.py", line 115, in _get_response
    response = self.process_exception_by_middleware(e, request)
  File "/usr/local/lib/python3.7/site-packages/django/core/handlers/base.py", line 113, in _get_response
    response = wrapped_callback(request, *callback_args, **callback_kwargs)
  File "/usr/local/lib/python3.7/site-packages/django/views/decorators/csrf.py", line 54, in wrapped_view
    return view_func(*args, **kwargs)
  File "/usr/local/lib/python3.7/site-packages/django/views/decorators/csrf.py", line 54, in wrapped_view
    return view_func(*args, **kwargs)
  File "/usr/local/lib/python3.7/site-packages/django/views/generic/base.py", line 71, in view
    return self.dispatch(request, *args, **kwargs)
  File "/usr/local/lib/python3.7/site-packages/rest_framework/views.py", line 505, in dispatch
    response = self.handle_exception(exc)
  File "/usr/local/lib/python3.7/site-packages/rest_framework/views.py", line 465, in handle_exception
    self.raise_uncaught_exception(exc)
  File "/usr/local/lib/python3.7/site-packages/rest_framework/views.py", line 476, in raise_uncaught_exception
    raise exc
  File "/usr/local/lib/python3.7/site-packages/rest_framework/views.py", line 502, in dispatch
    response = handler(request, *args, **kwargs)
  File "/usr/local/lib/python3.7/site-packages/rest_framework/decorators.py", line 50, in handler
    return func(*args, **kwargs)
  File "/Users/jacksonbursch/Documents/csuSeer/csuSeer-server/server/insert2DB/views.py", line 70, in createUser
    content_type = ContentType.objects.get(app_label='insert2DB', model='SystemConsumer')
  File "/usr/local/lib/python3.7/site-packages/django/db/models/manager.py", line 82, in manager_method
    return getattr(self.get_queryset(), name)(*args, **kwargs)
  File "/usr/local/lib/python3.7/site-packages/django/db/models/query.py", line 408, in get
    self.model._meta.object_name
django.contrib.contenttypes.models.ContentType.DoesNotExist: ContentType matching query does not exist.
2020-04-21 01:12:47,498 - django.utils.autoreload - INFO - /Users/jacksonbursch/Documents/csuSeer/csuSeer-server/server/insert2DB/views.py changed, reloading.
2020-04-21 01:12:57,441 - django.request - ERROR - Internal Server Error: /createUser/
Traceback (most recent call last):
  File "/usr/local/lib/python3.7/site-packages/djongo/sql2mongo/query.py", line 824, in parse
    return handler(self, statement)
  File "/usr/local/lib/python3.7/site-packages/djongo/sql2mongo/query.py", line 960, in _insert
    self._query.execute()
  File "/usr/local/lib/python3.7/site-packages/djongo/sql2mongo/query.py", line 430, in execute
    res = self.db_ref[self.left_table].insert_many(docs, ordered=False)
  File "/usr/local/lib/python3.7/site-packages/pymongo/collection.py", line 758, in insert_many
    blk.execute(write_concern, session=session)
  File "/usr/local/lib/python3.7/site-packages/pymongo/bulk.py", line 511, in execute
    return self.execute_command(generator, write_concern, session)
  File "/usr/local/lib/python3.7/site-packages/pymongo/bulk.py", line 349, in execute_command
    _raise_bulk_write_error(full_result)
  File "/usr/local/lib/python3.7/site-packages/pymongo/bulk.py", line 140, in _raise_bulk_write_error
    raise BulkWriteError(full_result)
pymongo.errors.BulkWriteError: batch op errors occurred

The above exception was the direct cause of the following exception:

Traceback (most recent call last):
  File "/usr/local/lib/python3.7/site-packages/django/core/handlers/exception.py", line 34, in inner
    response = get_response(request)
  File "/usr/local/lib/python3.7/site-packages/django/core/handlers/base.py", line 115, in _get_response
    response = self.process_exception_by_middleware(e, request)
  File "/usr/local/lib/python3.7/site-packages/django/core/handlers/base.py", line 113, in _get_response
    response = wrapped_callback(request, *callback_args, **callback_kwargs)
  File "/usr/local/lib/python3.7/site-packages/django/views/decorators/csrf.py", line 54, in wrapped_view
    return view_func(*args, **kwargs)
  File "/usr/local/lib/python3.7/site-packages/django/views/decorators/csrf.py", line 54, in wrapped_view
    return view_func(*args, **kwargs)
  File "/usr/local/lib/python3.7/site-packages/django/views/generic/base.py", line 71, in view
    return self.dispatch(request, *args, **kwargs)
  File "/usr/local/lib/python3.7/site-packages/rest_framework/views.py", line 505, in dispatch
    response = self.handle_exception(exc)
  File "/usr/local/lib/python3.7/site-packages/rest_framework/views.py", line 465, in handle_exception
    self.raise_uncaught_exception(exc)
  File "/usr/local/lib/python3.7/site-packages/rest_framework/views.py", line 476, in raise_uncaught_exception
    raise exc
  File "/usr/local/lib/python3.7/site-packages/rest_framework/views.py", line 502, in dispatch
    response = handler(request, *args, **kwargs)
  File "/usr/local/lib/python3.7/site-packages/rest_framework/decorators.py", line 50, in handler
    return func(*args, **kwargs)
  File "/Users/jacksonbursch/Documents/csuSeer/csuSeer-server/server/insert2DB/views.py", line 70, in createUser
    password = request.data.get('password'))
  File "/usr/local/lib/python3.7/site-packages/django/contrib/auth/models.py", line 151, in create_user
    return self._create_user(username, email, password, **extra_fields)
  File "/usr/local/lib/python3.7/site-packages/django/contrib/auth/models.py", line 145, in _create_user
    user.save(using=self._db)
  File "/usr/local/lib/python3.7/site-packages/django/contrib/auth/base_user.py", line 66, in save
    super().save(*args, **kwargs)
  File "/usr/local/lib/python3.7/site-packages/django/db/models/base.py", line 741, in save
    force_update=force_update, update_fields=update_fields)
  File "/usr/local/lib/python3.7/site-packages/django/db/models/base.py", line 779, in save_base
    force_update, using, update_fields,
  File "/usr/local/lib/python3.7/site-packages/django/db/models/base.py", line 870, in _save_table
    result = self._do_insert(cls._base_manager, using, fields, update_pk, raw)
  File "/usr/local/lib/python3.7/site-packages/django/db/models/base.py", line 908, in _do_insert
    using=using, raw=raw)
  File "/usr/local/lib/python3.7/site-packages/django/db/models/manager.py", line 82, in manager_method
    return getattr(self.get_queryset(), name)(*args, **kwargs)
  File "/usr/local/lib/python3.7/site-packages/django/db/models/query.py", line 1186, in _insert
    return query.get_compiler(using=using).execute_sql(return_id)
  File "/usr/local/lib/python3.7/site-packages/django/db/models/sql/compiler.py", line 1368, in execute_sql
    cursor.execute(sql, params)
  File "/usr/local/lib/python3.7/site-packages/django/db/backends/utils.py", line 99, in execute
    return super().execute(sql, params)
  File "/usr/local/lib/python3.7/site-packages/django/db/backends/utils.py", line 67, in execute
    return self._execute_with_wrappers(sql, params, many=False, executor=self._execute)
  File "/usr/local/lib/python3.7/site-packages/django/db/backends/utils.py", line 76, in _execute_with_wrappers
    return executor(sql, params, many, context)
  File "/usr/local/lib/python3.7/site-packages/django/db/backends/utils.py", line 84, in _execute
    return self.cursor.execute(sql, params)
  File "/usr/local/lib/python3.7/site-packages/djongo/cursor.py", line 53, in execute
    params)
  File "/usr/local/lib/python3.7/site-packages/djongo/sql2mongo/query.py", line 753, in __init__
    self.parse()
  File "/usr/local/lib/python3.7/site-packages/djongo/sql2mongo/query.py", line 837, in parse
    raise exe from e
djongo.sql2mongo.SQLDecodeError: FAILED SQL: INSERT INTO "auth_user" ("password", "last_login", "is_superuser", "username", "first_name", "last_name", "email", "is_staff", "is_active", "date_joined") VALUES (%(0)s, %(1)s, %(2)s, %(3)s, %(4)s, %(5)s, %(6)s, %(7)s, %(8)s, %(9)s)
Params: ['pbkdf2_sha256$150000$Kqzcst8xhm4F$msiftNJyDg/R49B/9Vl/ejQjD6huk2zYRyWOxX7agIs=', None, False, 'jaxon14', '', '', 'hello@gmail.com', False, True, datetime.datetime(2020, 4, 21, 1, 12, 57, 103435)]
Pymongo error: {'writeErrors': [{'index': 0, 'code': 11000, 'keyPattern': {'username': 1}, 'keyValue': {'username': 'jaxon14'}, 'errmsg': 'E11000 duplicate key error collection: csuSeerDB.auth_user index: username_1 dup key: { username: "jaxon14" }', 'op': {'id': 4, 'password': 'pbkdf2_sha256$150000$Kqzcst8xhm4F$msiftNJyDg/R49B/9Vl/ejQjD6huk2zYRyWOxX7agIs=', 'last_login': None, 'is_superuser': False, 'username': 'jaxon14', 'first_name': '', 'last_name': '', 'email': 'hello@gmail.com', 'is_staff': False, 'is_active': True, 'date_joined': datetime.datetime(2020, 4, 21, 1, 12, 57, 103435), '_id': ObjectId('5e9e4899f04d14f1aa234533')}}], 'writeConcernErrors': [], 'nInserted': 0, 'nUpserted': 0, 'nMatched': 0, 'nModified': 0, 'nRemoved': 0, 'upserted': []}
Version: 1.3.1
2020-04-21 01:13:19,814 - django.request - ERROR - Internal Server Error: /createUser/
Traceback (most recent call last):
  File "/usr/local/lib/python3.7/site-packages/django/core/handlers/exception.py", line 34, in inner
    response = get_response(request)
  File "/usr/local/lib/python3.7/site-packages/django/core/handlers/base.py", line 115, in _get_response
    response = self.process_exception_by_middleware(e, request)
  File "/usr/local/lib/python3.7/site-packages/django/core/handlers/base.py", line 113, in _get_response
    response = wrapped_callback(request, *callback_args, **callback_kwargs)
  File "/usr/local/lib/python3.7/site-packages/django/views/decorators/csrf.py", line 54, in wrapped_view
    return view_func(*args, **kwargs)
  File "/usr/local/lib/python3.7/site-packages/django/views/decorators/csrf.py", line 54, in wrapped_view
    return view_func(*args, **kwargs)
  File "/usr/local/lib/python3.7/site-packages/django/views/generic/base.py", line 71, in view
    return self.dispatch(request, *args, **kwargs)
  File "/usr/local/lib/python3.7/site-packages/rest_framework/views.py", line 505, in dispatch
    response = self.handle_exception(exc)
  File "/usr/local/lib/python3.7/site-packages/rest_framework/views.py", line 465, in handle_exception
    self.raise_uncaught_exception(exc)
  File "/usr/local/lib/python3.7/site-packages/rest_framework/views.py", line 476, in raise_uncaught_exception
    raise exc
  File "/usr/local/lib/python3.7/site-packages/rest_framework/views.py", line 502, in dispatch
    response = handler(request, *args, **kwargs)
  File "/usr/local/lib/python3.7/site-packages/rest_framework/decorators.py", line 50, in handler
    return func(*args, **kwargs)
  File "/Users/jacksonbursch/Documents/csuSeer/csuSeer-server/server/insert2DB/views.py", line 72, in createUser
    content_type = ContentType.objects.get(app_label='insert2DB', model='SystemConsumer')
  File "/usr/local/lib/python3.7/site-packages/django/db/models/manager.py", line 82, in manager_method
    return getattr(self.get_queryset(), name)(*args, **kwargs)
  File "/usr/local/lib/python3.7/site-packages/django/db/models/query.py", line 408, in get
    self.model._meta.object_name
django.contrib.contenttypes.models.ContentType.DoesNotExist: ContentType matching query does not exist.
2020-04-21 01:43:03,509 - django.utils.autoreload - INFO - /Users/jacksonbursch/Documents/csuSeer/csuSeer-server/server/insert2DB/views.py changed, reloading.
2020-04-21 01:48:07,759 - django.utils.autoreload - INFO - /Users/jacksonbursch/Documents/csuSeer/csuSeer-server/server/insert2DB/views.py changed, reloading.
2020-04-21 01:48:16,328 - django.request - ERROR - Internal Server Error: /permission/
Traceback (most recent call last):
  File "/usr/local/lib/python3.7/site-packages/django/core/handlers/exception.py", line 34, in inner
    response = get_response(request)
  File "/usr/local/lib/python3.7/site-packages/django/core/handlers/base.py", line 115, in _get_response
    response = self.process_exception_by_middleware(e, request)
  File "/usr/local/lib/python3.7/site-packages/django/core/handlers/base.py", line 113, in _get_response
    response = wrapped_callback(request, *callback_args, **callback_kwargs)
  File "/usr/local/lib/python3.7/site-packages/django/views/decorators/csrf.py", line 54, in wrapped_view
    return view_func(*args, **kwargs)
  File "/usr/local/lib/python3.7/site-packages/django/views/decorators/csrf.py", line 54, in wrapped_view
    return view_func(*args, **kwargs)
  File "/usr/local/lib/python3.7/site-packages/django/views/generic/base.py", line 71, in view
    return self.dispatch(request, *args, **kwargs)
  File "/usr/local/lib/python3.7/site-packages/rest_framework/views.py", line 505, in dispatch
    response = self.handle_exception(exc)
  File "/usr/local/lib/python3.7/site-packages/rest_framework/views.py", line 465, in handle_exception
    self.raise_uncaught_exception(exc)
  File "/usr/local/lib/python3.7/site-packages/rest_framework/views.py", line 476, in raise_uncaught_exception
    raise exc
  File "/usr/local/lib/python3.7/site-packages/rest_framework/views.py", line 502, in dispatch
    response = handler(request, *args, **kwargs)
  File "/usr/local/lib/python3.7/site-packages/rest_framework/decorators.py", line 50, in handler
    return func(*args, **kwargs)
  File "/Users/jacksonbursch/Documents/csuSeer/csuSeer-server/server/insert2DB/views.py", line 100, in givePerm
    user.user_permissions.add(permission)
  File "/usr/local/lib/python3.7/site-packages/django/db/models/fields/related_descriptors.py", line 938, in add
    through_defaults=through_defaults,
  File "/usr/local/lib/python3.7/site-packages/django/db/models/fields/related_descriptors.py", line 1065, in _add_items
    '%s__in' % target_field_name: new_ids,
  File "/usr/local/lib/python3.7/site-packages/django/db/models/query.py", line 892, in filter
    return self._filter_or_exclude(False, *args, **kwargs)
  File "/usr/local/lib/python3.7/site-packages/django/db/models/query.py", line 910, in _filter_or_exclude
    clone.query.add_q(Q(*args, **kwargs))
  File "/usr/local/lib/python3.7/site-packages/django/db/models/sql/query.py", line 1290, in add_q
    clause, _ = self._add_q(q_object, self.used_aliases)
  File "/usr/local/lib/python3.7/site-packages/django/db/models/sql/query.py", line 1318, in _add_q
    split_subq=split_subq, simple_col=simple_col,
  File "/usr/local/lib/python3.7/site-packages/django/db/models/sql/query.py", line 1251, in build_filter
    condition = self.build_lookup(lookups, col, value)
  File "/usr/local/lib/python3.7/site-packages/django/db/models/sql/query.py", line 1116, in build_lookup
    lookup = lookup_class(lhs, rhs)
  File "/usr/local/lib/python3.7/site-packages/django/db/models/lookups.py", line 20, in __init__
    self.rhs = self.get_prep_lookup()
  File "/usr/local/lib/python3.7/site-packages/django/db/models/fields/related_lookups.py", line 59, in get_prep_lookup
    self.rhs = [target_field.get_prep_value(v) for v in self.rhs]
  File "/usr/local/lib/python3.7/site-packages/django/db/models/fields/related_lookups.py", line 59, in <listcomp>
    self.rhs = [target_field.get_prep_value(v) for v in self.rhs]
  File "/usr/local/lib/python3.7/site-packages/django/db/models/fields/__init__.py", line 972, in get_prep_value
    return int(value)
TypeError: int() argument must be a string, a bytes-like object or a number, not 'QuerySet'
2020-04-21 01:48:25,263 - django.utils.autoreload - INFO - /Users/jacksonbursch/Documents/csuSeer/csuSeer-server/server/insert2DB/views.py changed, reloading.
2020-04-21 01:48:28,775 - django.request - ERROR - Internal Server Error: /permission/
Traceback (most recent call last):
  File "/usr/local/lib/python3.7/site-packages/django/core/handlers/exception.py", line 34, in inner
    response = get_response(request)
  File "/usr/local/lib/python3.7/site-packages/django/core/handlers/base.py", line 115, in _get_response
    response = self.process_exception_by_middleware(e, request)
  File "/usr/local/lib/python3.7/site-packages/django/core/handlers/base.py", line 113, in _get_response
    response = wrapped_callback(request, *callback_args, **callback_kwargs)
  File "/usr/local/lib/python3.7/site-packages/django/views/decorators/csrf.py", line 54, in wrapped_view
    return view_func(*args, **kwargs)
  File "/usr/local/lib/python3.7/site-packages/django/views/decorators/csrf.py", line 54, in wrapped_view
    return view_func(*args, **kwargs)
  File "/usr/local/lib/python3.7/site-packages/django/views/generic/base.py", line 71, in view
    return self.dispatch(request, *args, **kwargs)
  File "/usr/local/lib/python3.7/site-packages/rest_framework/views.py", line 505, in dispatch
    response = self.handle_exception(exc)
  File "/usr/local/lib/python3.7/site-packages/rest_framework/views.py", line 465, in handle_exception
    self.raise_uncaught_exception(exc)
  File "/usr/local/lib/python3.7/site-packages/rest_framework/views.py", line 476, in raise_uncaught_exception
    raise exc
  File "/usr/local/lib/python3.7/site-packages/rest_framework/views.py", line 502, in dispatch
    response = handler(request, *args, **kwargs)
  File "/usr/local/lib/python3.7/site-packages/rest_framework/decorators.py", line 50, in handler
    return func(*args, **kwargs)
  File "/Users/jacksonbursch/Documents/csuSeer/csuSeer-server/server/insert2DB/views.py", line 95, in givePerm
    permission = Permission.objects.get(codename ='can_write_sys', name ='Can write sys', content_type = ct)
  File "/usr/local/lib/python3.7/site-packages/django/db/models/manager.py", line 82, in manager_method
    return getattr(self.get_queryset(), name)(*args, **kwargs)
  File "/usr/local/lib/python3.7/site-packages/django/db/models/query.py", line 408, in get
    self.model._meta.object_name
django.contrib.auth.models.Permission.DoesNotExist: Permission matching query does not exist.
2020-04-21 01:49:41,640 - django.utils.autoreload - INFO - /Users/jacksonbursch/Documents/csuSeer/csuSeer-server/server/insert2DB/views.py changed, reloading.
2020-04-21 01:49:47,929 - django.request - ERROR - Internal Server Error: /permission/
Traceback (most recent call last):
  File "/usr/local/lib/python3.7/site-packages/django/core/handlers/exception.py", line 34, in inner
    response = get_response(request)
  File "/usr/local/lib/python3.7/site-packages/django/core/handlers/base.py", line 115, in _get_response
    response = self.process_exception_by_middleware(e, request)
  File "/usr/local/lib/python3.7/site-packages/django/core/handlers/base.py", line 113, in _get_response
    response = wrapped_callback(request, *callback_args, **callback_kwargs)
  File "/usr/local/lib/python3.7/site-packages/django/views/decorators/csrf.py", line 54, in wrapped_view
    return view_func(*args, **kwargs)
  File "/usr/local/lib/python3.7/site-packages/django/views/decorators/csrf.py", line 54, in wrapped_view
    return view_func(*args, **kwargs)
  File "/usr/local/lib/python3.7/site-packages/django/views/generic/base.py", line 71, in view
    return self.dispatch(request, *args, **kwargs)
  File "/usr/local/lib/python3.7/site-packages/rest_framework/views.py", line 505, in dispatch
    response = self.handle_exception(exc)
  File "/usr/local/lib/python3.7/site-packages/rest_framework/views.py", line 465, in handle_exception
    self.raise_uncaught_exception(exc)
  File "/usr/local/lib/python3.7/site-packages/rest_framework/views.py", line 476, in raise_uncaught_exception
    raise exc
  File "/usr/local/lib/python3.7/site-packages/rest_framework/views.py", line 502, in dispatch
    response = handler(request, *args, **kwargs)
  File "/usr/local/lib/python3.7/site-packages/rest_framework/decorators.py", line 50, in handler
    return func(*args, **kwargs)
  File "/Users/jacksonbursch/Documents/csuSeer/csuSeer-server/server/insert2DB/views.py", line 101, in givePerm
    user.user_permissions.add(all_permission)
NameError: name 'all_permission' is not defined
2020-04-21 01:49:54,817 - django.utils.autoreload - INFO - /Users/jacksonbursch/Documents/csuSeer/csuSeer-server/server/insert2DB/views.py changed, reloading.
2020-04-21 01:50:01,104 - django.request - ERROR - Internal Server Error: /permission/
Traceback (most recent call last):
  File "/usr/local/lib/python3.7/site-packages/django/core/handlers/exception.py", line 34, in inner
    response = get_response(request)
  File "/usr/local/lib/python3.7/site-packages/django/core/handlers/base.py", line 115, in _get_response
    response = self.process_exception_by_middleware(e, request)
  File "/usr/local/lib/python3.7/site-packages/django/core/handlers/base.py", line 113, in _get_response
    response = wrapped_callback(request, *callback_args, **callback_kwargs)
  File "/usr/local/lib/python3.7/site-packages/django/views/decorators/csrf.py", line 54, in wrapped_view
    return view_func(*args, **kwargs)
  File "/usr/local/lib/python3.7/site-packages/django/views/decorators/csrf.py", line 54, in wrapped_view
    return view_func(*args, **kwargs)
  File "/usr/local/lib/python3.7/site-packages/django/views/generic/base.py", line 71, in view
    return self.dispatch(request, *args, **kwargs)
  File "/usr/local/lib/python3.7/site-packages/rest_framework/views.py", line 505, in dispatch
    response = self.handle_exception(exc)
  File "/usr/local/lib/python3.7/site-packages/rest_framework/views.py", line 465, in handle_exception
    self.raise_uncaught_exception(exc)
  File "/usr/local/lib/python3.7/site-packages/rest_framework/views.py", line 476, in raise_uncaught_exception
    raise exc
  File "/usr/local/lib/python3.7/site-packages/rest_framework/views.py", line 502, in dispatch
    response = handler(request, *args, **kwargs)
  File "/usr/local/lib/python3.7/site-packages/rest_framework/decorators.py", line 50, in handler
    return func(*args, **kwargs)
  File "/Users/jacksonbursch/Documents/csuSeer/csuSeer-server/server/insert2DB/views.py", line 101, in givePerm
    user.user_permissions.add(all_permissions)
  File "/usr/local/lib/python3.7/site-packages/django/db/models/fields/related_descriptors.py", line 938, in add
    through_defaults=through_defaults,
  File "/usr/local/lib/python3.7/site-packages/django/db/models/fields/related_descriptors.py", line 1065, in _add_items
    '%s__in' % target_field_name: new_ids,
  File "/usr/local/lib/python3.7/site-packages/django/db/models/query.py", line 892, in filter
    return self._filter_or_exclude(False, *args, **kwargs)
  File "/usr/local/lib/python3.7/site-packages/django/db/models/query.py", line 910, in _filter_or_exclude
    clone.query.add_q(Q(*args, **kwargs))
  File "/usr/local/lib/python3.7/site-packages/django/db/models/sql/query.py", line 1290, in add_q
    clause, _ = self._add_q(q_object, self.used_aliases)
  File "/usr/local/lib/python3.7/site-packages/django/db/models/sql/query.py", line 1318, in _add_q
    split_subq=split_subq, simple_col=simple_col,
  File "/usr/local/lib/python3.7/site-packages/django/db/models/sql/query.py", line 1251, in build_filter
    condition = self.build_lookup(lookups, col, value)
  File "/usr/local/lib/python3.7/site-packages/django/db/models/sql/query.py", line 1116, in build_lookup
    lookup = lookup_class(lhs, rhs)
  File "/usr/local/lib/python3.7/site-packages/django/db/models/lookups.py", line 20, in __init__
    self.rhs = self.get_prep_lookup()
  File "/usr/local/lib/python3.7/site-packages/django/db/models/fields/related_lookups.py", line 59, in get_prep_lookup
    self.rhs = [target_field.get_prep_value(v) for v in self.rhs]
  File "/usr/local/lib/python3.7/site-packages/django/db/models/fields/related_lookups.py", line 59, in <listcomp>
    self.rhs = [target_field.get_prep_value(v) for v in self.rhs]
  File "/usr/local/lib/python3.7/site-packages/django/db/models/fields/__init__.py", line 972, in get_prep_value
    return int(value)
TypeError: int() argument must be a string, a bytes-like object or a number, not 'QuerySet'
2020-04-21 01:50:48,820 - django.utils.autoreload - INFO - /Users/jacksonbursch/Documents/csuSeer/csuSeer-server/server/insert2DB/views.py changed, reloading.
2020-04-21 01:50:53,371 - django.request - ERROR - Internal Server Error: /permission/
Traceback (most recent call last):
  File "/usr/local/lib/python3.7/site-packages/django/core/handlers/exception.py", line 34, in inner
    response = get_response(request)
  File "/usr/local/lib/python3.7/site-packages/django/core/handlers/base.py", line 115, in _get_response
    response = self.process_exception_by_middleware(e, request)
  File "/usr/local/lib/python3.7/site-packages/django/core/handlers/base.py", line 113, in _get_response
    response = wrapped_callback(request, *callback_args, **callback_kwargs)
  File "/usr/local/lib/python3.7/site-packages/django/views/decorators/csrf.py", line 54, in wrapped_view
    return view_func(*args, **kwargs)
  File "/usr/local/lib/python3.7/site-packages/django/views/decorators/csrf.py", line 54, in wrapped_view
    return view_func(*args, **kwargs)
  File "/usr/local/lib/python3.7/site-packages/django/views/generic/base.py", line 71, in view
    return self.dispatch(request, *args, **kwargs)
  File "/usr/local/lib/python3.7/site-packages/rest_framework/views.py", line 505, in dispatch
    response = self.handle_exception(exc)
  File "/usr/local/lib/python3.7/site-packages/rest_framework/views.py", line 465, in handle_exception
    self.raise_uncaught_exception(exc)
  File "/usr/local/lib/python3.7/site-packages/rest_framework/views.py", line 476, in raise_uncaught_exception
    raise exc
  File "/usr/local/lib/python3.7/site-packages/rest_framework/views.py", line 502, in dispatch
    response = handler(request, *args, **kwargs)
  File "/usr/local/lib/python3.7/site-packages/rest_framework/decorators.py", line 50, in handler
    return func(*args, **kwargs)
  File "/Users/jacksonbursch/Documents/csuSeer/csuSeer-server/server/insert2DB/views.py", line 101, in givePerm
    user.user_permissions.add(all_permissions)
  File "/usr/local/lib/python3.7/site-packages/django/db/models/fields/related_descriptors.py", line 938, in add
    through_defaults=through_defaults,
  File "/usr/local/lib/python3.7/site-packages/django/db/models/fields/related_descriptors.py", line 1065, in _add_items
    '%s__in' % target_field_name: new_ids,
  File "/usr/local/lib/python3.7/site-packages/django/db/models/query.py", line 892, in filter
    return self._filter_or_exclude(False, *args, **kwargs)
  File "/usr/local/lib/python3.7/site-packages/django/db/models/query.py", line 910, in _filter_or_exclude
    clone.query.add_q(Q(*args, **kwargs))
  File "/usr/local/lib/python3.7/site-packages/django/db/models/sql/query.py", line 1290, in add_q
    clause, _ = self._add_q(q_object, self.used_aliases)
  File "/usr/local/lib/python3.7/site-packages/django/db/models/sql/query.py", line 1318, in _add_q
    split_subq=split_subq, simple_col=simple_col,
  File "/usr/local/lib/python3.7/site-packages/django/db/models/sql/query.py", line 1251, in build_filter
    condition = self.build_lookup(lookups, col, value)
  File "/usr/local/lib/python3.7/site-packages/django/db/models/sql/query.py", line 1116, in build_lookup
    lookup = lookup_class(lhs, rhs)
  File "/usr/local/lib/python3.7/site-packages/django/db/models/lookups.py", line 20, in __init__
    self.rhs = self.get_prep_lookup()
  File "/usr/local/lib/python3.7/site-packages/django/db/models/fields/related_lookups.py", line 59, in get_prep_lookup
    self.rhs = [target_field.get_prep_value(v) for v in self.rhs]
  File "/usr/local/lib/python3.7/site-packages/django/db/models/fields/related_lookups.py", line 59, in <listcomp>
    self.rhs = [target_field.get_prep_value(v) for v in self.rhs]
  File "/usr/local/lib/python3.7/site-packages/django/db/models/fields/__init__.py", line 972, in get_prep_value
    return int(value)
TypeError: int() argument must be a string, a bytes-like object or a number, not 'QuerySet'
2020-04-21 01:51:51,652 - django.utils.autoreload - INFO - /Users/jacksonbursch/Documents/csuSeer/csuSeer-server/server/insert2DB/views.py changed, reloading.
2020-04-21 01:51:58,224 - django.request - ERROR - Internal Server Error: /permission/
Traceback (most recent call last):
  File "/usr/local/lib/python3.7/site-packages/django/core/handlers/exception.py", line 34, in inner
    response = get_response(request)
  File "/usr/local/lib/python3.7/site-packages/django/core/handlers/base.py", line 115, in _get_response
    response = self.process_exception_by_middleware(e, request)
  File "/usr/local/lib/python3.7/site-packages/django/core/handlers/base.py", line 113, in _get_response
    response = wrapped_callback(request, *callback_args, **callback_kwargs)
  File "/usr/local/lib/python3.7/site-packages/django/views/decorators/csrf.py", line 54, in wrapped_view
    return view_func(*args, **kwargs)
  File "/usr/local/lib/python3.7/site-packages/django/views/decorators/csrf.py", line 54, in wrapped_view
    return view_func(*args, **kwargs)
  File "/usr/local/lib/python3.7/site-packages/django/views/generic/base.py", line 71, in view
    return self.dispatch(request, *args, **kwargs)
  File "/usr/local/lib/python3.7/site-packages/rest_framework/views.py", line 505, in dispatch
    response = self.handle_exception(exc)
  File "/usr/local/lib/python3.7/site-packages/rest_framework/views.py", line 465, in handle_exception
    self.raise_uncaught_exception(exc)
  File "/usr/local/lib/python3.7/site-packages/rest_framework/views.py", line 476, in raise_uncaught_exception
    raise exc
  File "/usr/local/lib/python3.7/site-packages/rest_framework/views.py", line 502, in dispatch
    response = handler(request, *args, **kwargs)
  File "/usr/local/lib/python3.7/site-packages/rest_framework/decorators.py", line 50, in handler
    return func(*args, **kwargs)
  File "/Users/jacksonbursch/Documents/csuSeer/csuSeer-server/server/insert2DB/views.py", line 103, in givePerm
    user.user_permissions.add(all_permissions)
  File "/usr/local/lib/python3.7/site-packages/django/db/models/fields/related_descriptors.py", line 938, in add
    through_defaults=through_defaults,
  File "/usr/local/lib/python3.7/site-packages/django/db/models/fields/related_descriptors.py", line 1065, in _add_items
    '%s__in' % target_field_name: new_ids,
  File "/usr/local/lib/python3.7/site-packages/django/db/models/query.py", line 892, in filter
    return self._filter_or_exclude(False, *args, **kwargs)
  File "/usr/local/lib/python3.7/site-packages/django/db/models/query.py", line 910, in _filter_or_exclude
    clone.query.add_q(Q(*args, **kwargs))
  File "/usr/local/lib/python3.7/site-packages/django/db/models/sql/query.py", line 1290, in add_q
    clause, _ = self._add_q(q_object, self.used_aliases)
  File "/usr/local/lib/python3.7/site-packages/django/db/models/sql/query.py", line 1318, in _add_q
    split_subq=split_subq, simple_col=simple_col,
  File "/usr/local/lib/python3.7/site-packages/django/db/models/sql/query.py", line 1251, in build_filter
    condition = self.build_lookup(lookups, col, value)
  File "/usr/local/lib/python3.7/site-packages/django/db/models/sql/query.py", line 1116, in build_lookup
    lookup = lookup_class(lhs, rhs)
  File "/usr/local/lib/python3.7/site-packages/django/db/models/lookups.py", line 20, in __init__
    self.rhs = self.get_prep_lookup()
  File "/usr/local/lib/python3.7/site-packages/django/db/models/fields/related_lookups.py", line 59, in get_prep_lookup
    self.rhs = [target_field.get_prep_value(v) for v in self.rhs]
  File "/usr/local/lib/python3.7/site-packages/django/db/models/fields/related_lookups.py", line 59, in <listcomp>
    self.rhs = [target_field.get_prep_value(v) for v in self.rhs]
  File "/usr/local/lib/python3.7/site-packages/django/db/models/fields/__init__.py", line 972, in get_prep_value
    return int(value)
TypeError: int() argument must be a string, a bytes-like object or a number, not 'QuerySet'
2020-04-21 01:53:11,435 - django.utils.autoreload - INFO - /Users/jacksonbursch/Documents/csuSeer/csuSeer-server/server/insert2DB/views.py changed, reloading.
2020-04-21 01:53:19,107 - django.request - ERROR - Internal Server Error: /permission/
Traceback (most recent call last):
  File "/usr/local/lib/python3.7/site-packages/django/core/handlers/exception.py", line 34, in inner
    response = get_response(request)
  File "/usr/local/lib/python3.7/site-packages/django/core/handlers/base.py", line 115, in _get_response
    response = self.process_exception_by_middleware(e, request)
  File "/usr/local/lib/python3.7/site-packages/django/core/handlers/base.py", line 113, in _get_response
    response = wrapped_callback(request, *callback_args, **callback_kwargs)
  File "/usr/local/lib/python3.7/site-packages/django/views/decorators/csrf.py", line 54, in wrapped_view
    return view_func(*args, **kwargs)
  File "/usr/local/lib/python3.7/site-packages/django/views/decorators/csrf.py", line 54, in wrapped_view
    return view_func(*args, **kwargs)
  File "/usr/local/lib/python3.7/site-packages/django/views/generic/base.py", line 71, in view
    return self.dispatch(request, *args, **kwargs)
  File "/usr/local/lib/python3.7/site-packages/rest_framework/views.py", line 505, in dispatch
    response = self.handle_exception(exc)
  File "/usr/local/lib/python3.7/site-packages/rest_framework/views.py", line 465, in handle_exception
    self.raise_uncaught_exception(exc)
  File "/usr/local/lib/python3.7/site-packages/rest_framework/views.py", line 476, in raise_uncaught_exception
    raise exc
  File "/usr/local/lib/python3.7/site-packages/rest_framework/views.py", line 502, in dispatch
    response = handler(request, *args, **kwargs)
  File "/usr/local/lib/python3.7/site-packages/rest_framework/decorators.py", line 50, in handler
    return func(*args, **kwargs)
  File "/Users/jacksonbursch/Documents/csuSeer/csuSeer-server/server/insert2DB/views.py", line 103, in givePerm
    user.user_permissions.add(all_permissions)
  File "/usr/local/lib/python3.7/site-packages/django/db/models/fields/related_descriptors.py", line 938, in add
    through_defaults=through_defaults,
  File "/usr/local/lib/python3.7/site-packages/django/db/models/fields/related_descriptors.py", line 1065, in _add_items
    '%s__in' % target_field_name: new_ids,
  File "/usr/local/lib/python3.7/site-packages/django/db/models/query.py", line 892, in filter
    return self._filter_or_exclude(False, *args, **kwargs)
  File "/usr/local/lib/python3.7/site-packages/django/db/models/query.py", line 910, in _filter_or_exclude
    clone.query.add_q(Q(*args, **kwargs))
  File "/usr/local/lib/python3.7/site-packages/django/db/models/sql/query.py", line 1290, in add_q
    clause, _ = self._add_q(q_object, self.used_aliases)
  File "/usr/local/lib/python3.7/site-packages/django/db/models/sql/query.py", line 1318, in _add_q
    split_subq=split_subq, simple_col=simple_col,
  File "/usr/local/lib/python3.7/site-packages/django/db/models/sql/query.py", line 1251, in build_filter
    condition = self.build_lookup(lookups, col, value)
  File "/usr/local/lib/python3.7/site-packages/django/db/models/sql/query.py", line 1116, in build_lookup
    lookup = lookup_class(lhs, rhs)
  File "/usr/local/lib/python3.7/site-packages/django/db/models/lookups.py", line 20, in __init__
    self.rhs = self.get_prep_lookup()
  File "/usr/local/lib/python3.7/site-packages/django/db/models/fields/related_lookups.py", line 59, in get_prep_lookup
    self.rhs = [target_field.get_prep_value(v) for v in self.rhs]
  File "/usr/local/lib/python3.7/site-packages/django/db/models/fields/related_lookups.py", line 59, in <listcomp>
    self.rhs = [target_field.get_prep_value(v) for v in self.rhs]
  File "/usr/local/lib/python3.7/site-packages/django/db/models/fields/__init__.py", line 972, in get_prep_value
    return int(value)
TypeError: int() argument must be a string, a bytes-like object or a number, not 'QuerySet'
2020-04-21 01:53:31,971 - django.utils.autoreload - INFO - /Users/jacksonbursch/Documents/csuSeer/csuSeer-server/server/insert2DB/views.py changed, reloading.
2020-04-21 01:53:37,862 - django.request - ERROR - Internal Server Error: /permission/
Traceback (most recent call last):
  File "/usr/local/lib/python3.7/site-packages/django/core/handlers/exception.py", line 34, in inner
    response = get_response(request)
  File "/usr/local/lib/python3.7/site-packages/django/core/handlers/base.py", line 115, in _get_response
    response = self.process_exception_by_middleware(e, request)
  File "/usr/local/lib/python3.7/site-packages/django/core/handlers/base.py", line 113, in _get_response
    response = wrapped_callback(request, *callback_args, **callback_kwargs)
  File "/usr/local/lib/python3.7/site-packages/django/views/decorators/csrf.py", line 54, in wrapped_view
    return view_func(*args, **kwargs)
  File "/usr/local/lib/python3.7/site-packages/django/views/decorators/csrf.py", line 54, in wrapped_view
    return view_func(*args, **kwargs)
  File "/usr/local/lib/python3.7/site-packages/django/views/generic/base.py", line 71, in view
    return self.dispatch(request, *args, **kwargs)
  File "/usr/local/lib/python3.7/site-packages/rest_framework/views.py", line 505, in dispatch
    response = self.handle_exception(exc)
  File "/usr/local/lib/python3.7/site-packages/rest_framework/views.py", line 465, in handle_exception
    self.raise_uncaught_exception(exc)
  File "/usr/local/lib/python3.7/site-packages/rest_framework/views.py", line 476, in raise_uncaught_exception
    raise exc
  File "/usr/local/lib/python3.7/site-packages/rest_framework/views.py", line 502, in dispatch
    response = handler(request, *args, **kwargs)
  File "/usr/local/lib/python3.7/site-packages/rest_framework/decorators.py", line 50, in handler
    return func(*args, **kwargs)
  File "/Users/jacksonbursch/Documents/csuSeer/csuSeer-server/server/insert2DB/views.py", line 103, in givePerm
    user.user_permissions.addAll(all_permissions)
AttributeError: 'ManyRelatedManager' object has no attribute 'addAll'
2020-04-21 01:54:27,190 - django.utils.autoreload - INFO - /Users/jacksonbursch/Documents/csuSeer/csuSeer-server/server/insert2DB/models.py changed, reloading.
2020-04-21 01:54:33,553 - django.request - ERROR - Internal Server Error: /permission/
Traceback (most recent call last):
  File "/usr/local/lib/python3.7/site-packages/django/core/handlers/exception.py", line 34, in inner
    response = get_response(request)
  File "/usr/local/lib/python3.7/site-packages/django/core/handlers/base.py", line 115, in _get_response
    response = self.process_exception_by_middleware(e, request)
  File "/usr/local/lib/python3.7/site-packages/django/core/handlers/base.py", line 113, in _get_response
    response = wrapped_callback(request, *callback_args, **callback_kwargs)
  File "/usr/local/lib/python3.7/site-packages/django/views/decorators/csrf.py", line 54, in wrapped_view
    return view_func(*args, **kwargs)
  File "/usr/local/lib/python3.7/site-packages/django/views/decorators/csrf.py", line 54, in wrapped_view
    return view_func(*args, **kwargs)
  File "/usr/local/lib/python3.7/site-packages/django/views/generic/base.py", line 71, in view
    return self.dispatch(request, *args, **kwargs)
  File "/usr/local/lib/python3.7/site-packages/rest_framework/views.py", line 505, in dispatch
    response = self.handle_exception(exc)
  File "/usr/local/lib/python3.7/site-packages/rest_framework/views.py", line 465, in handle_exception
    self.raise_uncaught_exception(exc)
  File "/usr/local/lib/python3.7/site-packages/rest_framework/views.py", line 476, in raise_uncaught_exception
    raise exc
  File "/usr/local/lib/python3.7/site-packages/rest_framework/views.py", line 502, in dispatch
    response = handler(request, *args, **kwargs)
  File "/usr/local/lib/python3.7/site-packages/rest_framework/decorators.py", line 50, in handler
    return func(*args, **kwargs)
  File "/Users/jacksonbursch/Documents/csuSeer/csuSeer-server/server/insert2DB/views.py", line 103, in givePerm
    user.user_permissions.addAll(all_permissions)
AttributeError: 'ManyRelatedManager' object has no attribute 'addAll'
2020-04-21 01:54:44,511 - django.utils.autoreload - INFO - /Users/jacksonbursch/Documents/csuSeer/csuSeer-server/server/insert2DB/views.py changed, reloading.
2020-04-21 01:54:49,803 - django.request - ERROR - Internal Server Error: /permission/
Traceback (most recent call last):
  File "/usr/local/lib/python3.7/site-packages/django/core/handlers/exception.py", line 34, in inner
    response = get_response(request)
  File "/usr/local/lib/python3.7/site-packages/django/core/handlers/base.py", line 115, in _get_response
    response = self.process_exception_by_middleware(e, request)
  File "/usr/local/lib/python3.7/site-packages/django/core/handlers/base.py", line 113, in _get_response
    response = wrapped_callback(request, *callback_args, **callback_kwargs)
  File "/usr/local/lib/python3.7/site-packages/django/views/decorators/csrf.py", line 54, in wrapped_view
    return view_func(*args, **kwargs)
  File "/usr/local/lib/python3.7/site-packages/django/views/decorators/csrf.py", line 54, in wrapped_view
    return view_func(*args, **kwargs)
  File "/usr/local/lib/python3.7/site-packages/django/views/generic/base.py", line 71, in view
    return self.dispatch(request, *args, **kwargs)
  File "/usr/local/lib/python3.7/site-packages/rest_framework/views.py", line 505, in dispatch
    response = self.handle_exception(exc)
  File "/usr/local/lib/python3.7/site-packages/rest_framework/views.py", line 465, in handle_exception
    self.raise_uncaught_exception(exc)
  File "/usr/local/lib/python3.7/site-packages/rest_framework/views.py", line 476, in raise_uncaught_exception
    raise exc
  File "/usr/local/lib/python3.7/site-packages/rest_framework/views.py", line 502, in dispatch
    response = handler(request, *args, **kwargs)
  File "/usr/local/lib/python3.7/site-packages/rest_framework/decorators.py", line 50, in handler
    return func(*args, **kwargs)
  File "/Users/jacksonbursch/Documents/csuSeer/csuSeer-server/server/insert2DB/views.py", line 103, in givePerm
    user.user_permissions.add(all_permissions)
  File "/usr/local/lib/python3.7/site-packages/django/db/models/fields/related_descriptors.py", line 938, in add
    through_defaults=through_defaults,
  File "/usr/local/lib/python3.7/site-packages/django/db/models/fields/related_descriptors.py", line 1065, in _add_items
    '%s__in' % target_field_name: new_ids,
  File "/usr/local/lib/python3.7/site-packages/django/db/models/query.py", line 892, in filter
    return self._filter_or_exclude(False, *args, **kwargs)
  File "/usr/local/lib/python3.7/site-packages/django/db/models/query.py", line 910, in _filter_or_exclude
    clone.query.add_q(Q(*args, **kwargs))
  File "/usr/local/lib/python3.7/site-packages/django/db/models/sql/query.py", line 1290, in add_q
    clause, _ = self._add_q(q_object, self.used_aliases)
  File "/usr/local/lib/python3.7/site-packages/django/db/models/sql/query.py", line 1318, in _add_q
    split_subq=split_subq, simple_col=simple_col,
  File "/usr/local/lib/python3.7/site-packages/django/db/models/sql/query.py", line 1251, in build_filter
    condition = self.build_lookup(lookups, col, value)
  File "/usr/local/lib/python3.7/site-packages/django/db/models/sql/query.py", line 1116, in build_lookup
    lookup = lookup_class(lhs, rhs)
  File "/usr/local/lib/python3.7/site-packages/django/db/models/lookups.py", line 20, in __init__
    self.rhs = self.get_prep_lookup()
  File "/usr/local/lib/python3.7/site-packages/django/db/models/fields/related_lookups.py", line 59, in get_prep_lookup
    self.rhs = [target_field.get_prep_value(v) for v in self.rhs]
  File "/usr/local/lib/python3.7/site-packages/django/db/models/fields/related_lookups.py", line 59, in <listcomp>
    self.rhs = [target_field.get_prep_value(v) for v in self.rhs]
  File "/usr/local/lib/python3.7/site-packages/django/db/models/fields/__init__.py", line 972, in get_prep_value
    return int(value)
TypeError: int() argument must be a string, a bytes-like object or a number, not 'QuerySet'
2020-04-21 01:56:38,237 - django.utils.autoreload - INFO - /Users/jacksonbursch/Documents/csuSeer/csuSeer-server/server/insert2DB/views.py changed, reloading.
2020-04-21 01:56:55,583 - django.utils.autoreload - INFO - /Users/jacksonbursch/Documents/csuSeer/csuSeer-server/server/insert2DB/views.py changed, reloading.
2020-04-21 01:56:59,877 - django.request - ERROR - Internal Server Error: /permission/
Traceback (most recent call last):
  File "/usr/local/lib/python3.7/site-packages/django/core/handlers/exception.py", line 34, in inner
    response = get_response(request)
  File "/usr/local/lib/python3.7/site-packages/django/core/handlers/base.py", line 115, in _get_response
    response = self.process_exception_by_middleware(e, request)
  File "/usr/local/lib/python3.7/site-packages/django/core/handlers/base.py", line 113, in _get_response
    response = wrapped_callback(request, *callback_args, **callback_kwargs)
  File "/usr/local/lib/python3.7/site-packages/django/views/decorators/csrf.py", line 54, in wrapped_view
    return view_func(*args, **kwargs)
  File "/usr/local/lib/python3.7/site-packages/django/views/decorators/csrf.py", line 54, in wrapped_view
    return view_func(*args, **kwargs)
  File "/usr/local/lib/python3.7/site-packages/django/views/generic/base.py", line 71, in view
    return self.dispatch(request, *args, **kwargs)
  File "/usr/local/lib/python3.7/site-packages/rest_framework/views.py", line 505, in dispatch
    response = self.handle_exception(exc)
  File "/usr/local/lib/python3.7/site-packages/rest_framework/views.py", line 465, in handle_exception
    self.raise_uncaught_exception(exc)
  File "/usr/local/lib/python3.7/site-packages/rest_framework/views.py", line 476, in raise_uncaught_exception
    raise exc
  File "/usr/local/lib/python3.7/site-packages/rest_framework/views.py", line 502, in dispatch
    response = handler(request, *args, **kwargs)
  File "/usr/local/lib/python3.7/site-packages/rest_framework/decorators.py", line 50, in handler
    return func(*args, **kwargs)
  File "/Users/jacksonbursch/Documents/csuSeer/csuSeer-server/server/insert2DB/views.py", line 105, in givePerm
    group = Group.objects.create(name='foo', permissions=permissions)
NameError: name 'permissions' is not defined
2020-04-21 01:57:09,360 - django.utils.autoreload - INFO - /Users/jacksonbursch/Documents/csuSeer/csuSeer-server/server/insert2DB/views.py changed, reloading.
2020-04-21 01:57:14,269 - django.request - ERROR - Internal Server Error: /permission/
Traceback (most recent call last):
  File "/usr/local/lib/python3.7/site-packages/django/core/handlers/exception.py", line 34, in inner
    response = get_response(request)
  File "/usr/local/lib/python3.7/site-packages/django/core/handlers/base.py", line 115, in _get_response
    response = self.process_exception_by_middleware(e, request)
  File "/usr/local/lib/python3.7/site-packages/django/core/handlers/base.py", line 113, in _get_response
    response = wrapped_callback(request, *callback_args, **callback_kwargs)
  File "/usr/local/lib/python3.7/site-packages/django/views/decorators/csrf.py", line 54, in wrapped_view
    return view_func(*args, **kwargs)
  File "/usr/local/lib/python3.7/site-packages/django/views/decorators/csrf.py", line 54, in wrapped_view
    return view_func(*args, **kwargs)
  File "/usr/local/lib/python3.7/site-packages/django/views/generic/base.py", line 71, in view
    return self.dispatch(request, *args, **kwargs)
  File "/usr/local/lib/python3.7/site-packages/rest_framework/views.py", line 505, in dispatch
    response = self.handle_exception(exc)
  File "/usr/local/lib/python3.7/site-packages/rest_framework/views.py", line 465, in handle_exception
    self.raise_uncaught_exception(exc)
  File "/usr/local/lib/python3.7/site-packages/rest_framework/views.py", line 476, in raise_uncaught_exception
    raise exc
  File "/usr/local/lib/python3.7/site-packages/rest_framework/views.py", line 502, in dispatch
    response = handler(request, *args, **kwargs)
  File "/usr/local/lib/python3.7/site-packages/rest_framework/decorators.py", line 50, in handler
    return func(*args, **kwargs)
  File "/Users/jacksonbursch/Documents/csuSeer/csuSeer-server/server/insert2DB/views.py", line 105, in givePerm
    group = Group.objects.create(name='foo', permissions=all_permissions)
  File "/usr/local/lib/python3.7/site-packages/django/db/models/manager.py", line 82, in manager_method
    return getattr(self.get_queryset(), name)(*args, **kwargs)
  File "/usr/local/lib/python3.7/site-packages/django/db/models/query.py", line 420, in create
    obj = self.model(**kwargs)
  File "/usr/local/lib/python3.7/site-packages/django/db/models/base.py", line 496, in __init__
    _setattr(self, prop, kwargs[prop])
  File "/usr/local/lib/python3.7/site-packages/django/db/models/fields/related_descriptors.py", line 538, in __set__
    % self._get_set_deprecation_msg_params(),
TypeError: Direct assignment to the forward side of a many-to-many set is prohibited. Use permissions.set() instead.
2020-04-21 01:57:44,093 - django.utils.autoreload - INFO - /Users/jacksonbursch/Documents/csuSeer/csuSeer-server/server/insert2DB/views.py changed, reloading.
2020-04-21 01:57:47,248 - django.request - ERROR - Internal Server Error: /permission/
Traceback (most recent call last):
  File "/usr/local/lib/python3.7/site-packages/django/core/handlers/exception.py", line 34, in inner
    response = get_response(request)
  File "/usr/local/lib/python3.7/site-packages/django/core/handlers/base.py", line 115, in _get_response
    response = self.process_exception_by_middleware(e, request)
  File "/usr/local/lib/python3.7/site-packages/django/core/handlers/base.py", line 113, in _get_response
    response = wrapped_callback(request, *callback_args, **callback_kwargs)
  File "/usr/local/lib/python3.7/site-packages/django/views/decorators/csrf.py", line 54, in wrapped_view
    return view_func(*args, **kwargs)
  File "/usr/local/lib/python3.7/site-packages/django/views/decorators/csrf.py", line 54, in wrapped_view
    return view_func(*args, **kwargs)
  File "/usr/local/lib/python3.7/site-packages/django/views/generic/base.py", line 71, in view
    return self.dispatch(request, *args, **kwargs)
  File "/usr/local/lib/python3.7/site-packages/rest_framework/views.py", line 505, in dispatch
    response = self.handle_exception(exc)
  File "/usr/local/lib/python3.7/site-packages/rest_framework/views.py", line 465, in handle_exception
    self.raise_uncaught_exception(exc)
  File "/usr/local/lib/python3.7/site-packages/rest_framework/views.py", line 476, in raise_uncaught_exception
    raise exc
  File "/usr/local/lib/python3.7/site-packages/rest_framework/views.py", line 502, in dispatch
    response = handler(request, *args, **kwargs)
  File "/usr/local/lib/python3.7/site-packages/rest_framework/decorators.py", line 50, in handler
    return func(*args, **kwargs)
  File "/Users/jacksonbursch/Documents/csuSeer/csuSeer-server/server/insert2DB/views.py", line 105, in givePerm
    group = Group.objects.create(name='foo', permissions=all_permissions)
  File "/usr/local/lib/python3.7/site-packages/django/db/models/manager.py", line 82, in manager_method
    return getattr(self.get_queryset(), name)(*args, **kwargs)
  File "/usr/local/lib/python3.7/site-packages/django/db/models/query.py", line 420, in create
    obj = self.model(**kwargs)
  File "/usr/local/lib/python3.7/site-packages/django/db/models/base.py", line 496, in __init__
    _setattr(self, prop, kwargs[prop])
  File "/usr/local/lib/python3.7/site-packages/django/db/models/fields/related_descriptors.py", line 538, in __set__
    % self._get_set_deprecation_msg_params(),
TypeError: Direct assignment to the forward side of a many-to-many set is prohibited. Use permissions.set() instead.
2020-04-21 01:57:57,251 - django.utils.autoreload - INFO - /Users/jacksonbursch/Documents/csuSeer/csuSeer-server/server/insert2DB/views.py changed, reloading.
2020-04-21 01:58:01,405 - django.request - ERROR - Internal Server Error: /permission/
Traceback (most recent call last):
  File "/usr/local/lib/python3.7/site-packages/django/core/handlers/exception.py", line 34, in inner
    response = get_response(request)
  File "/usr/local/lib/python3.7/site-packages/django/core/handlers/base.py", line 115, in _get_response
    response = self.process_exception_by_middleware(e, request)
  File "/usr/local/lib/python3.7/site-packages/django/core/handlers/base.py", line 113, in _get_response
    response = wrapped_callback(request, *callback_args, **callback_kwargs)
  File "/usr/local/lib/python3.7/site-packages/django/views/decorators/csrf.py", line 54, in wrapped_view
    return view_func(*args, **kwargs)
  File "/usr/local/lib/python3.7/site-packages/django/views/decorators/csrf.py", line 54, in wrapped_view
    return view_func(*args, **kwargs)
  File "/usr/local/lib/python3.7/site-packages/django/views/generic/base.py", line 71, in view
    return self.dispatch(request, *args, **kwargs)
  File "/usr/local/lib/python3.7/site-packages/rest_framework/views.py", line 505, in dispatch
    response = self.handle_exception(exc)
  File "/usr/local/lib/python3.7/site-packages/rest_framework/views.py", line 465, in handle_exception
    self.raise_uncaught_exception(exc)
  File "/usr/local/lib/python3.7/site-packages/rest_framework/views.py", line 476, in raise_uncaught_exception
    raise exc
  File "/usr/local/lib/python3.7/site-packages/rest_framework/views.py", line 502, in dispatch
    response = handler(request, *args, **kwargs)
  File "/usr/local/lib/python3.7/site-packages/rest_framework/decorators.py", line 50, in handler
    return func(*args, **kwargs)
  File "/Users/jacksonbursch/Documents/csuSeer/csuSeer-server/server/insert2DB/views.py", line 105, in givePerm
    group = Group.objects.create(name='foo', permissions=all_permissions)
  File "/usr/local/lib/python3.7/site-packages/django/db/models/manager.py", line 82, in manager_method
    return getattr(self.get_queryset(), name)(*args, **kwargs)
  File "/usr/local/lib/python3.7/site-packages/django/db/models/query.py", line 420, in create
    obj = self.model(**kwargs)
  File "/usr/local/lib/python3.7/site-packages/django/db/models/base.py", line 496, in __init__
    _setattr(self, prop, kwargs[prop])
  File "/usr/local/lib/python3.7/site-packages/django/db/models/fields/related_descriptors.py", line 538, in __set__
    % self._get_set_deprecation_msg_params(),
TypeError: Direct assignment to the forward side of a many-to-many set is prohibited. Use permissions.set() instead.
2020-04-21 01:58:07,157 - django.utils.autoreload - INFO - /Users/jacksonbursch/Documents/csuSeer/csuSeer-server/server/insert2DB/views.py changed, reloading.
2020-04-21 01:58:14,918 - django.request - ERROR - Internal Server Error: /permission/
Traceback (most recent call last):
  File "/usr/local/lib/python3.7/site-packages/django/core/handlers/exception.py", line 34, in inner
    response = get_response(request)
  File "/usr/local/lib/python3.7/site-packages/django/core/handlers/base.py", line 115, in _get_response
    response = self.process_exception_by_middleware(e, request)
  File "/usr/local/lib/python3.7/site-packages/django/core/handlers/base.py", line 113, in _get_response
    response = wrapped_callback(request, *callback_args, **callback_kwargs)
  File "/usr/local/lib/python3.7/site-packages/django/views/decorators/csrf.py", line 54, in wrapped_view
    return view_func(*args, **kwargs)
  File "/usr/local/lib/python3.7/site-packages/django/views/decorators/csrf.py", line 54, in wrapped_view
    return view_func(*args, **kwargs)
  File "/usr/local/lib/python3.7/site-packages/django/views/generic/base.py", line 71, in view
    return self.dispatch(request, *args, **kwargs)
  File "/usr/local/lib/python3.7/site-packages/rest_framework/views.py", line 505, in dispatch
    response = self.handle_exception(exc)
  File "/usr/local/lib/python3.7/site-packages/rest_framework/views.py", line 465, in handle_exception
    self.raise_uncaught_exception(exc)
  File "/usr/local/lib/python3.7/site-packages/rest_framework/views.py", line 476, in raise_uncaught_exception
    raise exc
  File "/usr/local/lib/python3.7/site-packages/rest_framework/views.py", line 502, in dispatch
    response = handler(request, *args, **kwargs)
  File "/usr/local/lib/python3.7/site-packages/rest_framework/decorators.py", line 50, in handler
    return func(*args, **kwargs)
  File "/Users/jacksonbursch/Documents/csuSeer/csuSeer-server/server/insert2DB/views.py", line 107, in givePerm
    user.user_permissions.add(all_permissions)
  File "/usr/local/lib/python3.7/site-packages/django/db/models/fields/related_descriptors.py", line 938, in add
    through_defaults=through_defaults,
  File "/usr/local/lib/python3.7/site-packages/django/db/models/fields/related_descriptors.py", line 1065, in _add_items
    '%s__in' % target_field_name: new_ids,
  File "/usr/local/lib/python3.7/site-packages/django/db/models/query.py", line 892, in filter
    return self._filter_or_exclude(False, *args, **kwargs)
  File "/usr/local/lib/python3.7/site-packages/django/db/models/query.py", line 910, in _filter_or_exclude
    clone.query.add_q(Q(*args, **kwargs))
  File "/usr/local/lib/python3.7/site-packages/django/db/models/sql/query.py", line 1290, in add_q
    clause, _ = self._add_q(q_object, self.used_aliases)
  File "/usr/local/lib/python3.7/site-packages/django/db/models/sql/query.py", line 1318, in _add_q
    split_subq=split_subq, simple_col=simple_col,
  File "/usr/local/lib/python3.7/site-packages/django/db/models/sql/query.py", line 1251, in build_filter
    condition = self.build_lookup(lookups, col, value)
  File "/usr/local/lib/python3.7/site-packages/django/db/models/sql/query.py", line 1116, in build_lookup
    lookup = lookup_class(lhs, rhs)
  File "/usr/local/lib/python3.7/site-packages/django/db/models/lookups.py", line 20, in __init__
    self.rhs = self.get_prep_lookup()
  File "/usr/local/lib/python3.7/site-packages/django/db/models/fields/related_lookups.py", line 59, in get_prep_lookup
    self.rhs = [target_field.get_prep_value(v) for v in self.rhs]
  File "/usr/local/lib/python3.7/site-packages/django/db/models/fields/related_lookups.py", line 59, in <listcomp>
    self.rhs = [target_field.get_prep_value(v) for v in self.rhs]
  File "/usr/local/lib/python3.7/site-packages/django/db/models/fields/__init__.py", line 972, in get_prep_value
    return int(value)
TypeError: int() argument must be a string, a bytes-like object or a number, not 'QuerySet'
2020-04-21 01:58:26,055 - django.utils.autoreload - INFO - /Users/jacksonbursch/Documents/csuSeer/csuSeer-server/server/insert2DB/views.py changed, reloading.
2020-04-21 02:02:09,768 - django.utils.autoreload - INFO - /Users/jacksonbursch/Documents/csuSeer/csuSeer-server/server/insert2DB/views.py changed, reloading.
2020-04-21 02:02:44,411 - django.utils.autoreload - INFO - /Users/jacksonbursch/Documents/csuSeer/csuSeer-server/server/insert2DB/views.py changed, reloading.
2020-04-21 02:03:23,781 - django.utils.autoreload - INFO - /Users/jacksonbursch/Documents/csuSeer/csuSeer-server/server/insert2DB/views.py changed, reloading.
2020-04-21 02:07:56,550 - django.utils.autoreload - INFO - /Users/jacksonbursch/Documents/csuSeer/csuSeer-server/server/insert2DB/models.py changed, reloading.
2020-04-21 02:08:10,490 - django.utils.autoreload - INFO - /Users/jacksonbursch/Documents/csuSeer/csuSeer-server/server/insert2DB/views.py changed, reloading.
2020-04-21 02:19:16,324 - django.utils.autoreload - INFO - /Users/jacksonbursch/Documents/csuSeer/csuSeer-server/server/insert2DB/views.py changed, reloading.
2020-04-21 02:19:38,004 - django.utils.autoreload - INFO - /Users/jacksonbursch/Documents/csuSeer/csuSeer-server/server/insert2DB/views.py changed, reloading.
2020-04-21 02:20:46,050 - django.utils.autoreload - INFO - /Users/jacksonbursch/Documents/csuSeer/csuSeer-server/server/insert2DB/models.py changed, reloading.
2020-04-21 02:21:22,410 - django.utils.autoreload - INFO - /Users/jacksonbursch/Documents/csuSeer/csuSeer-server/server/insert2DB/models.py changed, reloading.
2020-04-21 02:21:26,098 - django.utils.autoreload - INFO - /Users/jacksonbursch/Documents/csuSeer/csuSeer-server/server/server/settings.py changed, reloading.
2020-04-21 02:25:12,019 - django.utils.autoreload - INFO - /Users/jacksonbursch/Documents/csuSeer/csuSeer-server/server/insert2DB/models.py changed, reloading.
